Workbook

Sheet Tong quan
A1: Phân tích hoạt động mô phỏng – Khóa C#: OOP + OOAD
A2: Đã xét: toàn bộ bài đọc (biểu tượng cuốn sách) và một số hoạt động phân tích có quá trình chạy rõ. Bài tập nộp, thảo luận, trắc nghiệm được giữ nguyên nên không liệt kê.
A4: Chương | B4: Nên làm | C4: Làm thêm nếu muốn | D4: Không cần | E4: Tổng số học liệu đã xét | F4: Đã duyệt OK | G4: Done | H4: Chưa done
A5: 1. Giới thiệu Lập trình hướng đối tượng (OOP) | B5: =COUNTIFS('Phan tich'!$B$2:$B$63,$A5,'Phan tich'!$F$2:$F$63,"Nên làm") | C5: =COUNTIFS('Phan tich'!$B$2:$B$63,$A5,'Phan tich'!$F$2:$F$63,"Làm thêm nếu muốn") | D5: =COUNTIFS('Phan tich'!$B$2:$B$63,$A5,'Phan tich'!$F$2:$F$63,"Không cần") | E5: =COUNTIF('Phan tich'!$B$2:$B$63,$A5) | F5: =COUNTIFS('Phan tich'!$B$2:$B$63,$A5,'Phan tich'!$N$2:$N$63,"OK") | G5: =COUNTIFS('Phan tich'!$B$2:$B$63,$A5,'Phan tich'!$G$2:$G$63,"Done") | H5: =COUNTIFS('Phan tich'!$B$2:$B$63,$A5,'Phan tich'!$G$2:$G$63,"Chưa done")
A6: 2. Đối tượng, Lớp và Đóng gói (Encapsulation) | B6: =COUNTIFS('Phan tich'!$B$2:$B$63,$A6,'Phan tich'!$F$2:$F$63,"Nên làm") | C6: =COUNTIFS('Phan tich'!$B$2:$B$63,$A6,'Phan tich'!$F$2:$F$63,"Làm thêm nếu muốn") | D6: =COUNTIFS('Phan tich'!$B$2:$B$63,$A6,'Phan tich'!$F$2:$F$63,"Không cần") | E6: =COUNTIF('Phan tich'!$B$2:$B$63,$A6) | F6: =COUNTIFS('Phan tich'!$B$2:$B$63,$A6,'Phan tich'!$N$2:$N$63,"OK") | G6: =COUNTIFS('Phan tich'!$B$2:$B$63,$A6,'Phan tich'!$G$2:$G$63,"Done") | H6: =COUNTIFS('Phan tich'!$B$2:$B$63,$A6,'Phan tich'!$G$2:$G$63,"Chưa done")
A7: 3. Kế thừa (Inheritance) và Tái sử dụng Mã | B7: =COUNTIFS('Phan tich'!$B$2:$B$63,$A7,'Phan tich'!$F$2:$F$63,"Nên làm") | C7: =COUNTIFS('Phan tich'!$B$2:$B$63,$A7,'Phan tich'!$F$2:$F$63,"Làm thêm nếu muốn") | D7: =COUNTIFS('Phan tich'!$B$2:$B$63,$A7,'Phan tich'!$F$2:$F$63,"Không cần") | E7: =COUNTIF('Phan tich'!$B$2:$B$63,$A7) | F7: =COUNTIFS('Phan tich'!$B$2:$B$63,$A7,'Phan tich'!$N$2:$N$63,"OK") | G7: =COUNTIFS('Phan tich'!$B$2:$B$63,$A7,'Phan tich'!$G$2:$G$63,"Done") | H7: =COUNTIFS('Phan tich'!$B$2:$B$63,$A7,'Phan tich'!$G$2:$G$63,"Chưa done")
A8: 4. Đa hình (Polymorphism) và Thiết kế linh hoạt | B8: =COUNTIFS('Phan tich'!$B$2:$B$63,$A8,'Phan tich'!$F$2:$F$63,"Nên làm") | C8: =COUNTIFS('Phan tich'!$B$2:$B$63,$A8,'Phan tich'!$F$2:$F$63,"Làm thêm nếu muốn") | D8: =COUNTIFS('Phan tich'!$B$2:$B$63,$A8,'Phan tich'!$F$2:$F$63,"Không cần") | E8: =COUNTIF('Phan tich'!$B$2:$B$63,$A8) | F8: =COUNTIFS('Phan tich'!$B$2:$B$63,$A8,'Phan tich'!$N$2:$N$63,"OK") | G8: =COUNTIFS('Phan tich'!$B$2:$B$63,$A8,'Phan tich'!$G$2:$G$63,"Done") | H8: =COUNTIFS('Phan tich'!$B$2:$B$63,$A8,'Phan tich'!$G$2:$G$63,"Chưa done")
A9: 5. Trừu tượng (Abstraction) với Abstract Class và Interface | B9: =COUNTIFS('Phan tich'!$B$2:$B$63,$A9,'Phan tich'!$F$2:$F$63,"Nên làm") | C9: =COUNTIFS('Phan tich'!$B$2:$B$63,$A9,'Phan tich'!$F$2:$F$63,"Làm thêm nếu muốn") | D9: =COUNTIFS('Phan tich'!$B$2:$B$63,$A9,'Phan tich'!$F$2:$F$63,"Không cần") | E9: =COUNTIF('Phan tich'!$B$2:$B$63,$A9) | F9: =COUNTIFS('Phan tich'!$B$2:$B$63,$A9,'Phan tich'!$N$2:$N$63,"OK") | G9: =COUNTIFS('Phan tich'!$B$2:$B$63,$A9,'Phan tich'!$G$2:$G$63,"Done") | H9: =COUNTIFS('Phan tich'!$B$2:$B$63,$A9,'Phan tich'!$G$2:$G$63,"Chưa done")
A10: 6. Giới thiệu Phân tích & Thiết kế hướng đối tượng (OOAD) | B10: =COUNTIFS('Phan tich'!$B$2:$B$63,$A10,'Phan tich'!$F$2:$F$63,"Nên làm") | C10: =COUNTIFS('Phan tich'!$B$2:$B$63,$A10,'Phan tich'!$F$2:$F$63,"Làm thêm nếu muốn") | D10: =COUNTIFS('Phan tich'!$B$2:$B$63,$A10,'Phan tich'!$F$2:$F$63,"Không cần") | E10: =COUNTIF('Phan tich'!$B$2:$B$63,$A10) | F10: =COUNTIFS('Phan tich'!$B$2:$B$63,$A10,'Phan tich'!$N$2:$N$63,"OK") | G10: =COUNTIFS('Phan tich'!$B$2:$B$63,$A10,'Phan tich'!$G$2:$G$63,"Done") | H10: =COUNTIFS('Phan tich'!$B$2:$B$63,$A10,'Phan tich'!$G$2:$G$63,"Chưa done")
A11: 7. Mối quan hệ giữa các lớp và Sơ đồ lớp UML (Class Diagram) | B11: =COUNTIFS('Phan tich'!$B$2:$B$63,$A11,'Phan tich'!$F$2:$F$63,"Nên làm") | C11: =COUNTIFS('Phan tich'!$B$2:$B$63,$A11,'Phan tich'!$F$2:$F$63,"Làm thêm nếu muốn") | D11: =COUNTIFS('Phan tich'!$B$2:$B$63,$A11,'Phan tich'!$F$2:$F$63,"Không cần") | E11: =COUNTIF('Phan tich'!$B$2:$B$63,$A11) | F11: =COUNTIFS('Phan tich'!$B$2:$B$63,$A11,'Phan tich'!$N$2:$N$63,"OK") | G11: =COUNTIFS('Phan tich'!$B$2:$B$63,$A11,'Phan tich'!$G$2:$G$63,"Done") | H11: =COUNTIFS('Phan tich'!$B$2:$B$63,$A11,'Phan tich'!$G$2:$G$63,"Chưa done")
A12: 8. Nguyên tắc thiết kế hướng đối tượng cơ bản và Mã nguồn sạch | B12: =COUNTIFS('Phan tich'!$B$2:$B$63,$A12,'Phan tich'!$F$2:$F$63,"Nên làm") | C12: =COUNTIFS('Phan tich'!$B$2:$B$63,$A12,'Phan tich'!$F$2:$F$63,"Làm thêm nếu muốn") | D12: =COUNTIFS('Phan tich'!$B$2:$B$63,$A12,'Phan tich'!$F$2:$F$63,"Không cần") | E12: =COUNTIF('Phan tich'!$B$2:$B$63,$A12) | F12: =COUNTIFS('Phan tich'!$B$2:$B$63,$A12,'Phan tich'!$N$2:$N$63,"OK") | G12: =COUNTIFS('Phan tich'!$B$2:$B$63,$A12,'Phan tich'!$G$2:$G$63,"Done") | H12: =COUNTIFS('Phan tich'!$B$2:$B$63,$A12,'Phan tich'!$G$2:$G$63,"Chưa done")
A13: 9. Xây dựng dự án thực tế với OOP & OOAD | B13: =COUNTIFS('Phan tich'!$B$2:$B$63,$A13,'Phan tich'!$F$2:$F$63,"Nên làm") | C13: =COUNTIFS('Phan tich'!$B$2:$B$63,$A13,'Phan tich'!$F$2:$F$63,"Làm thêm nếu muốn") | D13: =COUNTIFS('Phan tich'!$B$2:$B$63,$A13,'Phan tich'!$F$2:$F$63,"Không cần") | E13: =COUNTIF('Phan tich'!$B$2:$B$63,$A13) | F13: =COUNTIFS('Phan tich'!$B$2:$B$63,$A13,'Phan tich'!$N$2:$N$63,"OK") | G13: =COUNTIFS('Phan tich'!$B$2:$B$63,$A13,'Phan tich'!$G$2:$G$63,"Done") | H13: =COUNTIFS('Phan tich'!$B$2:$B$63,$A13,'Phan tich'!$G$2:$G$63,"Chưa done")
A14: Tổng | B14: =SUM(B5:B13) | C14: =SUM(C5:C13) | D14: =SUM(D5:D13) | E14: =SUM(E5:E13) | F14: =SUM(F5:F13) | G14: =SUM(G5:G13) | H14: =SUM(H5:H13)
A16: Cách đọc file
A17: Nên làm | B17: Bài đọc có quá trình chạy (luồng gọi hàm, bộ nhớ, đối tượng) mà chữ và ảnh tĩnh khó diễn tả.
A18: Làm thêm nếu muốn | B18: Có ích nhưng ý chính đã được bài khác hoặc bài đọc truyền tải khá tốt.
A19: Không cần | B19: Lý thuyết, tóm tắt, hướng dẫn ra quyết định, hoặc trùng ý: ghi rõ dùng lại mô phỏng nào.
A20: Cột Trạng thái | B20: Done = đã viết mô phỏng và kiểm thử, file nằm ở cột Đường dẫn. Chưa done = chưa làm.
A21: Cột Duyệt | B21: Ô vàng ở sheet 'Phan tich': chọn OK / Sửa / Bỏ và ghi ý kiến; bảng trên tự đếm số đã duyệt.
A23: Quy ước kỹ thuật (giữ theo mẫu khóa Thuật toán)
A24: Khung trang | B24: Mỗi bài 1 file HTML độc lập, giữ CSS và engine snapshot (Bước tiếp / Chạy hết / Làm lại), có chế độ tối, rộng 390px không tràn.
A25: Mở rộng cho OOP | B25: Khung bộ nhớ thêm vùng 'Đối tượng' (heap): hộp có tên lớp và mã #1, #2, liệt kê trường; biến tham chiếu hiện →Car#1. Hộp không còn ai tham chiếu thì mờ đi.
A26: Mở rộng cho UML (chương 6-7) | B26: Thêm thành phần vẽ hộp lớp UML và các mũi tên quan hệ bằng SVG thuần; khung #code dùng được cho văn bản (đề bài, kịch bản Use Case).
A27: Lỗi biên dịch / ngoại lệ | B27: Hiện ở console bằng màu đỏ, kèm mã lỗi C# thật (CS0122, CS0144, CS0534, CS0535, NullReferenceException, InvalidCastException...).
A28: Không quiz, không thử thách | B28: Chỉ quan sát và bấm từng bước; tab dùng để đổi tình huống.
A29: Thư mục | B29: oop_ooad/<chuong>/<bai-hoc>/<hoc-lieu>/index.html, đẩy lên GitHub Pages như khóa Thuật toán.

Sheet Phan tich
A1: STT | B1: Chương (Module) | C1: Bài học (Lesson) | D1: Học liệu (Activity) | E1: Loại học liệu | F1: Mức đề xuất | G1: Trạng thái | H1: Ý chính cần mô phỏng | I1: Cách hoạt động của mô phỏng | J1: Dạng giao diện | K1: Đường dẫn file (đề xuất) | L1: Link GitHub Pages (sau khi đẩy) | M1: Ghi chú | N1: Duyệt (OK / Sửa / Bỏ) | O1: Ý kiến của bạn | P1: Nội dung cũ | Q1: Nội dung mới | R1: Đã cập nhật nội dung
A2: 3 | B2: 1. Giới thiệu Lập trình hướng đối tượng (OOP) | C2: Giới thiệu Lập trình hướng đối tượng (OOP) | D2: Các khái niệm cốt lõi của OOP (Tổng quan) | E2: Bài đọc | F2: Nên làm | G2: Done | H2: Nhìn nhanh 4 trụ cột bằng một ví dụ nhỏ cho mỗi trụ cột. | I2: 4 tab, mỗi tab 3-4 bước. Tab Đóng gói: acc.Deposit(-50) bị chặn, Balance giữ nguyên. Tab Kế thừa: Dog : Animal, dog.Eat() dùng phương thức của lớp cha. Tab Đa hình: Animal a lần lượt trỏ Dog, Cat; cùng lời gọi a.Speak() in Gâu, Meo. Tab Trừu tượng: chỉ gọi car.Start(), các bước bên trong ẩn (mờ). Bộ nhớ hiện hộp đối tượng và giá trị trường. | J2: 1 cột, nhiều tab | K2: oop_ooad/gioi-thieu-lap-trinh-huong-doi-tuong-oop/gioi-thieu-lap-trinh-huong-doi-tuong-oop/cac-khai-niem-cot-loi-cua-oop-tong-quan/index.html | L2: https://codegym-vn.github.io/programming-course-demos/oop_ooad/gioi-thieu-lap-trinh-huong-doi-tuong-oop/gioi-thieu-lap-trinh-huong-doi-tuong-oop/cac-khai-niem-cot-loi-cua-oop-tong-quan/ | M2: Mỗi tab chỉ là bản rút gọn; chi tiết có ở chương 2 đến 5. | P2: Giới thiệu về các khái niệm cốt lõi của OOP Lập trình hướng đối tượng (OOP) không chỉ là một phương pháp lập trình; nó là một triết lý được xây dựng dựa trên một bộ các nguyên tắc cơ bản. Việc nắm vững các nguyên tắc này là chìa khóa để viết mã nguồn mạnh mẽ, dễ bảo trì và mở rộng. Trong trang này, chúng ta sẽ cùng tìm hiểu tổng quan về sáu khái niệm cốt lõi của OOP, tạo nền tảng vững chắc cho hành trình học tập C# và OOP của bạn. Các khái niệm này bao gồm: Đối tượng (Object), Lớp (Class), Đóng gói (Encapsulation), Kế thừa (Inheritance), Đa hình (Polymorphism) và Trừu tượng (Abstraction). Đối tượng (Object) và Lớp (Class) Đối tượng (Object) Như bạn đã tìm hiểu ở trang trước, OOP xoay quanh khái niệm 'đối tượng'. Một đối tượng là một thực thể trong thế giới thực hoặc trong hệ thống phần mềm của chúng ta, có hai đặc điểm chính: Trạng thái (State): Là các thuộc tính, dữ liệu mô tả đối tượng tại một thời điểm nhất định. Ví dụ, một đối tượng Car có thể có trạng thái như Color (màu sắc), Model (kiểu xe), CurrentSpeed (tốc độ hiện tại). Hành vi (Behavior): Là các hành động mà đối tượng có thể thực hiện hoặc các hành động có thể tác động lên đối tượng. Ví dụ, đối tượng Car có thể có các hành vi như Accelerate() (tăng tốc), Brake() (phanh), Turn() (rẽ). Lớp (Class) Nếu đối tượng là một thực thể cụ thể, thì lớp chính là bản thiết kế, khuôn mẫu hay định nghĩa để tạo ra các đối tượng đó. Một lớp không phải là một đối tượng; nó chỉ mô tả cách một đối tượng thuộc loại đó sẽ trông như thế nào và cách nó sẽ hoạt động. Hãy hình dung một bản thiết kế nhà (lớp). Từ bản thiết kế đó, bạn có thể xây dựng nhiều ngôi nhà khác nhau (đối tượng), mỗi ngôi nhà có thể có màu sơn khác nhau, nhưng tất cả đều tuân theo cấu trúc và chức năng được định nghĩa trong bản thiết kế. Trong C#, chúng ta định nghĩa một lớp bằng từ khóa class. // Định nghĩa một lớp tên là 'Car' public class Car { // Trạng thái (Thuộc tính) public string Model { get; set; } public string Color { get; set; } public int CurrentSpeed { get; private set; } = 0; // Tốc độ ban đầu là 0 // Hành vi (Phương thức) public void Accelerate(int increment) { CurrentSpeed += increment; Console.WriteLine($"Xe {Color} {Model} đang tăng tốc lên {CurrentSpeed} km/h."); } public void Brake() { CurrentSpeed = 0; Console.WriteLine($"Xe {Color} {Model} đã dừng lại."); } } // Để tạo một đối tượng (instance) từ lớp Car: // Car myCar = new Car(); // myCar.Model = "Toyota Camry"; // myCar.Color = "Đỏ"; // myCar.Accelerate(60); Đóng gói (Encapsulation) Đóng gói là nguyên tắc che giấu dữ liệu và hành vi bên trong một đối tượng, chỉ cho phép truy cập thông qua một giao diện công khai được kiểm soát. Điều này có nghĩa là các chi tiết triển khai nội bộ của một đối tượng được giữ kín, và các đối tượng khác không thể trực tiếp thay đổi trạng thái nội bộ một cách tùy tiện. Mục đích chính của đóng gói là: Bảo toàn tính toàn vẹn của dữ liệu: Ngăn chặn việc thay đổi dữ liệu một cách không hợp lệ. Giảm sự phụ thuộc: Khi thay đổi cách một đối tượng hoạt động nội bộ, các đối tượng khác sử dụng nó không cần phải thay đổi, miễn là giao diện công khai vẫn giữ nguyên. Tăng tính mô-đun: Mỗi đối tượng trở thành một "hộp đen" tự chứa, dễ dàng quản lý và tái sử dụng. Trong C#, đóng gói thường được thực hiện thông qua: Bộ chỉ định truy cập (Access Modifiers): Như public, private, protected. Ví dụ, một thuộc tính private chỉ có thể được truy cập từ bên trong lớp đó. Thuộc tính (Properties): Cung cấp các phương thức get và set để kiểm soát cách dữ liệu được đọc và ghi. public class BankAccount { private decimal _balance; // Dữ liệu nội bộ được bảo vệ (private) public BankAccount(decimal initialBalance) { if (initialBalance < 0) { throw new ArgumentException("Số dư ban đầu không thể âm."); } _balance = initialBalance; } // Phương thức công khai để thay đổi trạng thái (hành vi) public void Deposit(decimal amount) { if (amount > 0) { _balance += amount; Console.WriteLine($"Đã gửi {amount:C}. Số dư mới: {_balance:C}"); } } // Phương thức công khai để đọc trạng thái (hành vi) public decimal GetBalance() { return _balance; } } Trong ví dụ trên, _balance được đóng gói. Bạn không thể trực tiếp gán giá trị cho _balance từ bên ngoài lớp BankAccount; thay vào đó, bạn phải sử dụng phương thức Deposit() hoặc GetBalance(), đảm bảo rằng mọi thao tác đều được kiểm soát. Kế thừa (Inheritance) Kế thừa là một cơ chế cho phép một lớp (lớp con hoặc lớp dẫn xuất) nhận tất cả các thuộc tính và phương thức từ một lớp khác (lớp cha hoặc lớp cơ sở). Nguyên tắc này giúp thiết lập mối quan hệ "là một loại" (is-a relationship) giữa các lớp, ví dụ: "Một Carlà một loạiVehicle". Lợi ích chính của kế thừa là: Tái sử dụng mã: Tránh viết lại cùng một mã nhiều lần. Các tính năng chung được định nghĩa ở lớp cha và được các lớp con tự động kế thừa. Mở rộng tính năng: Lớp con có thể thêm các thuộc tính và phương thức mới hoặc ghi đè (override) các phương thức của lớp cha để cung cấp hành vi chuyên biệt hơn. Tạo cấu trúc phân cấp: Giúp tổ chức mã nguồn một cách logic, phản ánh các mối quan hệ tự nhiên giữa các thực thể. Trong C#, chúng ta sử dụng dấu hai chấm : để chỉ ra mối quan hệ kế thừa. public class Vehicle // Lớp cha (Base Class) { public string Manufacturer { get; set; } public int Year { get; set; } public void StartEngine() { Console.WriteLine("Động cơ đã khởi động."); } } public class Car : Vehicle // Lớp con (Derived Class) kế thừa từ Vehicle { public int NumberOfDoors { get; set; } public void Honk() { Console.WriteLine("Bíp bíp!"); } } // Đối tượng Car có thể sử dụng các thuộc tính và phương thức của Vehicle // Car myCar = new Car(); // myCar.Manufacturer = "Honda"; // Thuộc tính từ Vehicle // myCar.StartEngine(); // Phương thức từ Vehicle // myCar.Honk(); // Phương thức riêng của Car Đa hình (Polymorphism) Đa hình có nghĩa là "nhiều hình thái". Trong OOP, nó đề cập đến khả năng một đối tượng có thể mang nhiều hình thái khác nhau hoặc khả năng một phương thức có thể được gọi trên các đối tượng thuộc các lớp khác nhau và thực hiện các hành vi khác nhau tùy thuộc vào loại đối tượng cụ thể. Đa hình cho phép chúng ta: Viết mã linh hoạt và mở rộng: Có thể xử lý các đối tượng thuộc các lớp khác nhau thông qua một giao diện chung. Giảm sự phức tạp: Không cần biết chính xác loại đối tượng nào đang được xử lý tại thời điểm biên dịch; hành vi đúng sẽ được gọi tại thời điểm chạy. Trong C#, đa hình thường được triển khai thông qua: Ghi đè phương thức (Method Overriding): Lớp con cung cấp một triển khai cụ thể cho một phương thức đã được định nghĩa trong lớp cha. Để làm điều này, phương thức trong lớp cha phải được đánh dấu bằng từ khóa virtual, và phương thức trong lớp con phải được đánh dấu bằng từ khóa override. Giao diện (Interfaces): Định nghĩa một tập hợp các phương thức mà các lớp phải triển khai. public class Animal { public virtual void MakeSound() // Phương thức virtual có thể được ghi đè { Console.WriteLine("Một con vật tạo ra âm thanh."); } } public class Dog : Animal { public override void MakeSound() // Ghi đè phương thức MakeSound của Animal { Console.WriteLine("Gâu gâu!"); } } public class Cat : Animal { public override void MakeSound() // Ghi đè phương thức MakeSound của Animal { Console.WriteLine("Meo meo!"); } } // Ví dụ về đa hình: // Animal myDog = new Dog(); // Animal myCat = new Cat(); // myDog.MakeSound(); // In ra "Gâu gâu!" // myCat.MakeSound(); // In ra "Meo meo!" Trừu tượng (Abstraction) Trừu tượng là nguyên tắc tập trung vào những gì một đối tượng làm (giao diện công khai) thay vì làm như thế nào (chi tiết triển khai nội bộ). Nó cho phép chúng ta ẩn đi những chi tiết phức tạp không cần thiết từ người dùng hoặc từ các phần khác của hệ thống, chỉ phơi bày những thông tin và chức năng quan trọng. Lợi ích của trừu tượng: Quản lý độ phức tạp: Đơn giản hóa các hệ thống phức tạp bằng cách chia chúng thành các phần nhỏ hơn, dễ hiểu hơn. Tăng tính dễ sử dụng: Người dùng chỉ cần biết cách tương tác với giao diện công khai mà không cần lo lắng về các hoạt động bên trong. Dễ dàng thay đổi và bảo trì: Các chi tiết triển khai có thể thay đổi mà không ảnh hưởng đến các đối tượng sử dụng giao diện trừu tượng. Trong C#, trừu tượng được triển khai thông qua: Lớp trừu tượng (Abstract Classes): Các lớp không thể được khởi tạo trực tiếp và có thể chứa các phương thức trừu tượng (không có phần thân) mà các lớp con phải triển khai. Giao diện (Interfaces): Định nghĩa một hợp đồng về các phương thức mà một lớp phải triển khai, nhưng không cung cấp bất kỳ triển khai nào. public abstract class Shape // Lớp trừu tượng { public abstract double CalculateArea(); // Phương thức trừu tượng, không có phần thân public void Display() { Console.WriteLine($"Đây là một hình có diện tích: {CalculateArea()}"); } } public class Circle : Shape { public double Radius { get; set; } public Circle(double radius) { Radius = radius; } public override double CalculateArea() // Lớp con phải triển khai phương thức trừu tượng { return Math.PI * Radius * Radius; } } public class Rectangle : Shape { public double Width { get; set; } public double Height { get; set; } public Rectangle(double width, double height) { Width = width; Height = height; } public override double CalculateArea() // Lớp con phải triển khai phương thức trừu tượng { return Width * Height; } } // Shape s1 = new Circle(5); // s1.Display(); // In ra "Đây là một hình có diện tích: 78.53981633974483" // Shape s2 = new Rectangle(4, 6); // s2.Display(); // In ra "Đây là một hình có diện tích: 24" Trong ví dụ này, người dùng chỉ cần biết rằng mọi Shape đều có thể CalculateArea() và Display(), mà không cần biết chi tiết cách mỗi hình cụ thể (như Circle hay Rectangle) tính toán diện tích của nó. Đó chính là trừu tượng. | Q2: # Các khái niệm cốt lõi của OOP ## Mục tiêu học tập Sau bài học này, bạn có thể: - Kể tên sáu khái niệm cốt lõi của OOP: đối tượng, lớp, đóng gói, kế thừa, đa hình và trừu tượng. - Phân biệt lớp (bản thiết kế) với đối tượng (thực thể được tạo ra từ lớp). - Giải thích mỗi trụ cột bằng một ví dụ C# ngắn. - Nhận ra từ khóa C# gắn với từng trụ cột: `private`, dấu `:`, `virtual` và `override`, `abstract`. - Quan sát từng bước chạy của bốn trụ cột bằng hoạt động mô phỏng. ## Tổng quan Lập trình hướng đối tượng (OOP) không chỉ là một cách viết mã. Nó dựa trên một bộ nguyên tắc giúp mã nguồn **mạnh mẽ, dễ bảo trì và dễ mở rộng**. Bài này giới thiệu nhanh sáu khái niệm cốt lõi, làm nền cho các chương sau: - **Đối tượng (Object)** và **Lớp (Class)**: hai khái niệm nền tảng. - **Đóng gói (Encapsulation)**, **Kế thừa (Inheritance)**, **Đa hình (Polymorphism)** và **Trừu tượng (Abstraction)**: bốn trụ cột của OOP. ## Đối tượng và lớp ### Đối tượng (Object) Đối tượng là một thực thể trong thế giới thực hoặc trong phần mềm, có hai đặc điểm chính: - **Trạng thái (State):** dữ liệu mô tả đối tượng tại một thời điểm. Ví dụ, một đối tượng `Car` có `Color` (màu), `Model` (kiểu xe), `CurrentSpeed` (tốc độ hiện tại). - **Hành vi (Behavior):** những việc đối tượng có thể làm. Ví dụ, `Car` có thể `Accelerate()` (tăng tốc), `Brake()` (phanh). ### Lớp (Class) Lớp là **bản thiết kế** dùng để tạo ra đối tượng. Lớp mô tả đối tượng sẽ có những gì và làm được gì, nhưng bản thân lớp chưa phải là một đối tượng. Hãy hình dung một bản thiết kế nhà (lớp). Từ đó bạn xây được nhiều ngôi nhà (đối tượng), mỗi nhà một màu sơn khác nhau nhưng cùng cấu trúc. Trong C#, ta định nghĩa lớp bằng từ khóa `class` và tạo đối tượng bằng từ khóa `new`: ```csharp using System; public class Car { // Trạng thái public string Model { get; set; } public string Color { get; set; } public int CurrentSpeed { get; private set; } = 0; // Hành vi public void Accelerate(int increment) { CurrentSpeed += increment; Console.WriteLine($"Xe {Color} {Model} đang tăng tốc lên {CurrentSpeed} km/h."); } public void Brake() { CurrentSpeed = 0; Console.WriteLine($"Xe {Color} {Model} đã dừng lại."); } } public class Program { public static void Main() { Car myCar = new Car(); myCar.Model = "Toyota Camry"; myCar.Color = "Đỏ"; myCar.Accelerate(60); // Xe Đỏ Toyota Camry đang tăng tốc lên 60 km/h. } } ``` ## Bốn trụ cột của OOP ### Đóng gói (Encapsulation) Đóng gói là che giấu dữ liệu bên trong đối tượng và chỉ cho phép thay đổi qua các phương thức công khai có kiểm soát. Nhờ đó: - **Dữ liệu luôn hợp lệ:** không ai gán tùy tiện một giá trị sai. - **Giảm phụ thuộc:** đổi cách làm bên trong thì code bên ngoài không phải sửa, miễn là phương thức công khai giữ nguyên. - **Tăng tính mô-đun:** mỗi đối tượng là một "hộp đen" dễ quản lý và tái sử dụng. Trong C#, đóng gói thường dùng từ khóa kiểm soát truy cập (`public`, `private`, `protected`) và thuộc tính (property): ```csharp using System; public class BankAccount { private decimal _balance; // dữ liệu nội bộ, được bảo vệ public BankAccount(decimal initialBalance) { if (initialBalance < 0) { throw new ArgumentException("Số dư ban đầu không thể âm."); } _balance = initialBalance; } public void Deposit(decimal amount) { if (amount > 0) { _balance += amount; Console.WriteLine($"Đã gửi {amount:C}. Số dư mới: {_balance:C}"); } } public decimal GetBalance() { return _balance; } } ``` Bạn không thể gán trực tiếp `_balance` từ bên ngoài lớp. Muốn đổi số dư, phải gọi `Deposit()`, và `Deposit()` chỉ chấp nhận số tiền lớn hơn 0. ### Kế thừa (Inheritance) Kế thừa cho phép một lớp (lớp con) nhận lại những gì lớp khác (lớp cha) đã có. Hai lớp có quan hệ **"là một loại"** (is-a): `Dog` là một loại `Animal`. Lợi ích: - **Tái sử dụng mã:** viết một lần ở lớp cha, mọi lớp con dùng được. - **Mở rộng:** lớp con thêm thành viên mới hoặc ghi đè hành vi của lớp cha. - **Cấu trúc phân cấp:** mã phản ánh đúng quan hệ giữa các thực thể. Trong C#, ta dùng dấu hai chấm `:` để kế thừa: ```csharp using System; public class Animal // lớp cha { public void Eat() { Console.WriteLine("Đang ăn"); } } public class Dog : Animal // lớp con kế thừa Animal { public void Bark() { Console.WriteLine("Gâu!"); } } public class Program { public static void Main() { Dog dog = new Dog(); dog.Eat(); // phương thức của Animal dog.Bark(); // phương thức riêng của Dog } } ``` ### Đa hình (Polymorphism) Đa hình nghĩa là "nhiều hình thái": cùng một lời gọi phương thức, nhưng hành vi thay đổi theo **đối tượng thật** mà biến đang trỏ tới. Nhờ đó ta viết mã linh hoạt, dễ mở rộng, và không cần biết trước chính xác loại đối tượng nào sẽ được xử lý. Trong C#, đa hình thường dùng **ghi đè phương thức**: lớp cha đánh dấu `virtual`, lớp con đánh dấu `override`. Ngoài ra còn có giao diện (interface). ```csharp using System; public class Animal { public virtual void Speak() { Console.WriteLine("Một con vật kêu."); } } public class Dog : Animal { public override void Speak() { Console.WriteLine("Gâu"); } } public class Cat : Animal { public override void Speak() { Console.WriteLine("Meo"); } } public class Program { public static void Main() { Animal a = new Dog(); a.Speak(); // Gâu a = new Cat(); a.Speak(); // Meo } } ``` ### Trừu tượng (Abstraction) Trừu tượng tập trung vào việc đối tượng **làm gì**, không phải **làm như thế nào**. Giống như lái xe: bạn chỉ cần bấm nút Start, không cần biết động cơ bên trong hoạt động ra sao. Lợi ích: - **Giảm độ phức tạp:** người dùng chỉ thấy phần cần dùng. - **Dễ sử dụng:** chỉ cần biết cách gọi, không cần biết bên trong. - **Dễ thay đổi:** sửa chi tiết bên trong mà không ảnh hưởng nơi gọi. Trong C#, trừu tượng được thể hiện bằng **lớp trừu tượng** (`abstract class`) và **giao diện** (`interface`). ```csharp using System; public abstract class Shape { public abstract double CalculateArea(); // không có thân, lớp con phải tự cài đặt public void Display() { Console.WriteLine($"Diện tích: {CalculateArea()}"); } } public class Rectangle : Shape { public double Width { get; set; } public double Height { get; set; } public Rectangle(double width, double height) { Width = width; Height = height; } public override double CalculateArea() => Width * Height; } public class Program { public static void Main() { Shape s = new Rectangle(4, 6); s.Display(); // Diện tích: 24 } } ``` Người dùng chỉ cần biết mọi `Shape` đều có `Display()`. Cách mỗi hình tính diện tích là chi tiết bên trong. ### So sánh nhanh bốn trụ cột | Trụ cột | Ý chính | Từ khóa C# thường gặp | |---|---|---| | Đóng gói | Giấu dữ liệu, chỉ đổi qua phương thức có kiểm soát | `private`, `public`, property | | Kế thừa | Lớp con dùng lại những gì lớp cha có | `:` | | Đa hình | Cùng lời gọi, hành vi tùy đối tượng thật | `virtual`, `override` | | Trừu tượng | Chỉ lộ phần cần dùng, ẩn chi tiết bên trong | `abstract`, `interface` | ## Hoạt động: Bốn trụ cột qua từng bước chạy Mô phỏng dưới đây có bốn tab, mỗi tab là một ví dụ nhỏ của một trụ cột. Hãy thao tác theo thứ tự sau, bấm **Bước tiếp** để chạy từng dòng: - Mở tab **Đóng gói**. `balance` là `private`. `Deposit(100)` hợp lệ nên `balance` tăng lên 100. `Deposit(-50)` bị chặn vì `x` không lớn hơn 0, nên `balance` vẫn là 100. - Chuyển sang tab **Kế thừa**. Lớp `Dog : Animal` không tự viết gì, nhưng `dog.Eat()` vẫn chạy được vì `Eat()` được thừa hưởng từ `Animal`. - Mở tab **Đa hình**. Dòng `a.Speak()` được gọi hai lần. Lần đầu `a` trỏ tới `Dog` nên in "Gâu". Sau khi gán `a = new Cat()`, lần hai in "Meo". Hãy để ý đối tượng `Dog` cũ mờ đi vì không còn biến nào trỏ tới. - Mở tab **Trừu tượng**. Người dùng chỉ gọi `car.Start()`. Các bước bên trong (`CheckFuel()`, `TurnKey()`, `running = true`) ban đầu bị ẩn mờ, rồi sáng lên khi `Start()` chạy. ``` <iframe src="https://codegym-vn.github.io/programming-course-demos/oop_ooad/gioi-thieu-lap-trinh-huong-doi-tuong-oop/gioi-thieu-lap-trinh-huong-doi-tuong-oop/cac-khai-niem-cot-loi-cua-oop-tong-quan/" title="Bốn trụ cột của OOP" style="border:0;" allowfullscreen></iframe> ``` Điều rút ra: bốn ví dụ khác nhau nhưng có chung một ý. Mỗi trụ cột giải quyết một vấn đề cụ thể. Đóng gói giữ dữ liệu hợp lệ, kế thừa tránh viết lại mã, đa hình cho phép một lời gọi phục vụ nhiều loại đối tượng, trừu tượng che bớt chi tiết không cần thiết. Các chương sau sẽ đi sâu vào từng trụ cột. ## Tóm tắt - **Đối tượng** có trạng thái và hành vi. **Lớp** là bản thiết kế để tạo ra đối tượng bằng `new`. - **Đóng gói** giấu dữ liệu bằng `private` và chỉ cho đổi qua phương thức có kiểm tra. - **Kế thừa** dùng `:` để lớp con tái sử dụng và mở rộng lớp cha (quan hệ "là một loại"). - **Đa hình** dùng `virtual` và `override`: cùng một lời gọi, kết quả tùy đối tượng thật. - **Trừu tượng** dùng `abstract class` hoặc `interface` để chỉ lộ phần cần dùng và ẩn chi tiết bên trong. - Bốn trụ cột bổ trợ cho nhau để mã nguồn dễ bảo trì và mở rộng.
A3: 4 | B3: 2. Đối tượng, Lớp và Đóng gói (Encapsulation) | C3: Giới thiệu về Lớp và Đối tượng trong C# | D3: Lớp là gì? Đối tượng là gì? | E3: Bài đọc | F3: Nên làm | G3: Done | H3: Lớp là khuôn, đối tượng là bản cụ thể được tạo bằng new. | I3: Code: class Car { string Color; int Speed; } rồi Car a = new Car(); a.Color = "Đỏ"; Car b = new Car(); b.Color = "Xanh";. Bộ nhớ chia 2 vùng: Biến (a, b giữ tham chiếu →Car#1, →Car#2) và Đối tượng (2 hộp Car với trường riêng). Mỗi bước tô sáng hộp vừa tạo/vừa đổi. Ghi chú cuối: một lớp, nhiều đối tượng, mỗi đối tượng có dữ liệu riêng. | J3: 1 cột | K3: oop_ooad/doi-tuong-lop-va-dong-goi-encapsulation/gioi-thieu-ve-lop-va-doi-tuong-trong-c-sharp/lop-la-gi-doi-tuong-la-gi/index.html | L3: https://codegym-vn.github.io/programming-course-demos/oop_ooad/doi-tuong-lop-va-dong-goi-encapsulation/gioi-thieu-ve-lop-va-doi-tuong-trong-c-sharp/lop-la-gi-doi-tuong-la-gi/ | M3: Cần mở rộng khung #mem: thêm vùng Đối tượng (heap) dạng hộp có tên lớp, mã #1, #2 và các trường. | P3: Lập trình Hướng đối tượng (OOP): Một Cách Nhìn Mới về Giải Quyết Vấn Đề Trong lập trình thủ tục truyền thống, chúng ta thường tập trung vào trình tự các bước thực hiện để giải quyết một vấn đề. Dữ liệu và các hàm thao tác trên dữ liệu thường được tách rời. Tuy nhiên, khi các hệ thống trở nên phức tạp hơn, cách tiếp cận này có thể dẫn đến khó khăn trong việc quản lý, mở rộng và bảo trì mã nguồn. Lập trình hướng đối tượng (OOP) ra đời để giải quyết những thách thức này bằng cách cung cấp một mô hình mạnh mẽ hơn, gần gũi hơn với cách chúng ta nhận thức thế giới thực. Thay vì chỉ tập trung vào "làm gì", OOP tập trung vào "ai/cái gì" thực hiện hành động đó. Nền tảng của OOP chính là hai khái niệm cơ bản: Lớp (Class) và Đối tượng (Object). Chúng ta sẽ cùng ôn lại và đi sâu vào ý nghĩa của chúng. Lớp là gì? Bản Thiết Kế của Thế Giới Số Hãy tưởng tượng bạn muốn xây dựng một ngôi nhà. Bạn sẽ không xây dựng ngay lập tức, mà trước tiên bạn cần một bản thiết kế chi tiết. Bản thiết kế này mô tả mọi thứ về ngôi nhà: số phòng, kích thước các phòng, vị trí cửa sổ, loại vật liệu, v.v. Nó là một khuôn mẫu, một kế hoạch tổng thể. Trong lập trình hướng đối tượng, Lớp (Class) chính là bản thiết kế đó. Một lớp là một khuôn mẫu (template) hoặc bản thiết kế (blueprint) để tạo ra các đối tượng. Nó định nghĩa cấu trúc và hành vi chung mà tất cả các đối tượng được tạo ra từ lớp đó sẽ có. Một lớp không phải là một thực thể cụ thể; nó là một định nghĩa trừu tượng về một loại đối tượng. Một lớp bao gồm hai thành phần chính: Thuộc tính (Attributes/Fields/Properties): Đây là dữ liệu, trạng thái hoặc đặc điểm của đối tượng. Tương tự như màu sơn, số bánh xe của một chiếc ô tô, hoặc tên, tuổi của một người. Phương thức (Methods): Đây là các hành vi hoặc chức năng mà đối tượng có thể thực hiện. Ví dụ, một chiếc ô tô có thể Lái(), Phanh(); một người có thể Ăn(), Ngủ(). Ví dụ về một Lớp trong C#: Hãy xem xét lớp Oto (Car) dưới đây. Đây là một bản thiết kế định nghĩa những đặc điểm và hành vi mà một chiếc ô tô sẽ có. class Oto { // Thuộc tính (Attributes) - Đặc điểm của chiếc xe public string HangSanXuat; public string MauSac; public int SoBanhXe; // Mặc định là 4 // Phương thức (Methods) - Hành vi của chiếc xe public void KhoiDong() { // Mã để khởi động xe Console.WriteLine("Xe đang khởi động..."); } public void DiChuyen(int tocDo) { // Mã để điều khiển xe di chuyển Console.WriteLine($"Xe đang di chuyển với tốc độ {tocDo} km/h."); } public void DungLai() { // Mã để dừng xe Console.WriteLine("Xe đã dừng lại."); } } Trong ví dụ trên, Oto là một lớp. Nó định nghĩa rằng mọi chiếc ô tô sẽ có HangSanXuat, MauSac, SoBanhXe và có thể thực hiện các hành động KhoiDong(), DiChuyen(), DungLai(). Bản thân lớp Oto không phải là một chiếc xe cụ thể mà bạn có thể lái được; nó chỉ là khuôn mẫu để tạo ra chúng. Đối tượng là gì? Thể Hiện Cụ Thể Từ Bản Thiết Kế Tiếp tục với ví dụ ngôi nhà: Sau khi có bản thiết kế, bạn có thể sử dụng nó để xây dựng một ngôi nhà cụ thể. Ngôi nhà đó là một thực thể vật lý, có địa chỉ cụ thể, có thể ở được, có màu sơn riêng, v.v. Trong OOP, Đối tượng (Object) chính là thực thể cụ thể đó. Một đối tượng là một thể hiện (instance) của một lớp. Nó là một thực thể cụ thể, tồn tại trong bộ nhớ máy tính, được tạo ra dựa trên định nghĩa của một lớp. Mỗi đối tượng có trạng thái (state) riêng (tức là các giá trị cụ thể cho các thuộc tính của nó) và có thể thực hiện các hành vi được định nghĩa trong lớp của nó. Từ bản thiết kế Oto ở trên, bạn có thể tạo ra vô số đối tượng ô tô khác nhau. Mỗi đối tượng sẽ là một chiếc ô tô độc lập với các đặc điểm riêng: Đối tượng 1:myCar HangSanXuat: "Toyota" MauSac: "Đỏ" SoBanhXe: 4 Đối tượng 2:yourCar HangSanXuat: "Honda" MauSac: "Xanh" SoBanhXe: 4 Đối tượng 3:taxiCar HangSanXuat: "Hyundai" MauSac: "Trắng" SoBanhXe: 4 Mỗi đối tượng này là một thực thể riêng biệt, chiếm một vùng nhớ riêng và có thể hoạt động độc lập. Mặc dù tất cả chúng đều được tạo ra từ cùng một lớp Oto, nhưng chúng có thể có các giá trị thuộc tính khác nhau, tạo nên sự đa dạng và độc lập. Phân Biệt Lớp và Đối tượng: Từ Khái Quát đến Cụ Thể Để củng cố sự hiểu biết, chúng ta hãy cùng nhìn lại sự khác biệt cơ bản giữa lớp và đối tượng: Hãy nhớ rằng, lớp là một khái niệm, một sự trừu tượng; đối tượng là hiện thực hóa của khái niệm đó. Vai trò của Lớp và Đối tượng trong Mô hình hóa Thế giới Thực Mục tiêu chính của lập trình hướng đối tượng là giúp chúng ta mô hình hóa các thực thể và mối quan hệ trong thế giới thực một cách tự nhiên và hiệu quả hơn. Lớp và đối tượng đóng vai trò trung tâm trong quá trình này: Trừu tượng hóa (Abstraction): Lớp giúp chúng ta trừu tượng hóa các khái niệm phức tạp thành các đơn vị dễ quản lý. Thay vì nghĩ về hàng trăm dòng mã, chúng ta nghĩ về "một sinh viên" hoặc "một đơn hàng". Đóng gói (Encapsulation): Lớp cho phép chúng ta nhóm dữ liệu (thuộc tính) và hành vi (phương thức) liên quan lại với nhau thành một đơn vị duy nhất (đối tượng). Điều này giúp bảo vệ dữ liệu và làm cho mã dễ hiểu, dễ bảo trì hơn. (Chúng ta sẽ tìm hiểu sâu hơn về Đóng gói trong các bài học sau). Tái sử dụng (Reusability): Khi đã định nghĩa một lớp, bạn có thể tái sử dụng nó để tạo ra nhiều đối tượng khác nhau mà không cần viết lại mã từ đầu. Điều này giúp tiết kiệm thời gian và công sức phát triển. Tổ chức mã nguồn: Lớp giúp cấu trúc chương trình một cách rõ ràng và logic, phản ánh cấu trúc của vấn đề trong thế giới thực. Điều này làm cho các dự án lớn trở nên dễ quản lý hơn. Bằng cách sử dụng lớp để định nghĩa các loại thực thể và tạo ra các đối tượng cụ thể từ chúng, chúng ta có thể xây dựng các ứng dụng phức tạp một cách có hệ thống, phản ánh chân thực các thực thể và tương tác trong thế giới mà chúng ta đang cố gắng mô hình hóa. Đây chính là sức mạnh và vẻ đẹp của lập trình hướng đối tượng. | Q3: # Lớp là gì? Đối tượng là gì? ## Mục tiêu học tập Sau bài học này, bạn có thể: - Giải thích lớp (class) là bản thiết kế và đối tượng (object) là thực thể được tạo ra từ bản thiết kế đó. - Phân biệt hai thành phần chính của lớp: trường (dữ liệu) và phương thức (hành vi). - Viết một lớp đơn giản trong C# và tạo nhiều đối tượng từ nó bằng từ khóa `new`. - Nhận ra rằng mỗi đối tượng giữ dữ liệu riêng, dù cùng một lớp. - Quan sát từng bước chạy của lớp `Car` và hai đối tượng bằng hoạt động mô phỏng. ## Từ "làm gì" sang "ai làm" Trong lập trình thủ tục, ta hay nghĩ theo các bước: làm việc này, rồi làm việc kia. Dữ liệu và các hàm xử lý dữ liệu thường nằm tách rời. Khi chương trình lớn dần, cách này khó quản lý và khó bảo trì. Lập trình hướng đối tượng (OOP) nhìn theo hướng khác, gần với thế giới thật hơn. Ta không chỉ hỏi "làm gì", mà hỏi thêm "**ai** hoặc **cái gì** làm việc đó". Nền tảng của cách nhìn này là hai khái niệm: **lớp** và **đối tượng**. ## Lớp (Class) Hãy tưởng tượng bạn muốn xây một ngôi nhà. Trước hết bạn cần một **bản thiết kế**: số phòng, kích thước, vị trí cửa sổ, vật liệu. Bản thiết kế chưa phải là một ngôi nhà bạn có thể ở. Trong OOP, **lớp** chính là bản thiết kế đó: - Lớp là **khuôn mẫu** (template) để tạo ra các đối tượng. - Lớp mô tả những gì mọi đối tượng thuộc loại đó **có** và **làm được**. - Lớp không phải là một thực thể cụ thể. Nó chỉ là định nghĩa về một loại đối tượng. Một lớp có hai thành phần chính: - **Trường (Field):** dữ liệu mô tả đặc điểm hay trạng thái của đối tượng. Ví dụ: màu sắc và tốc độ của xe, tên và tuổi của một người. - **Phương thức (Method):** hành vi mà đối tượng có thể thực hiện. Ví dụ: xe có thể khởi động, chạy, dừng. Dưới đây là lớp `Car` có hai trường `Color` (màu) và `Speed` (tốc độ), cùng một phương thức `Run()`: ```csharp using System; public class Car { // Trường: đặc điểm của chiếc xe public string Color; public int Speed; // Phương thức: hành vi của chiếc xe public void Run() { Console.WriteLine("Xe " + Color + " đang chạy với tốc độ " + Speed + " km/h."); } } ``` Lớp `Car` nói rằng: mọi chiếc xe đều có `Color` và `Speed`, và đều chạy được. Bản thân lớp `Car` không phải một chiếc xe để lái. Viết xong lớp thì bộ nhớ vẫn chưa có chiếc xe nào. ## Đối tượng (Object) Có bản thiết kế rồi, bạn xây một ngôi nhà cụ thể: có địa chỉ, có màu sơn riêng, ở được. Trong OOP, đó là **đối tượng**: - Đối tượng là một **thể hiện** (instance) của lớp. - Đối tượng là thực thể cụ thể, **tồn tại trong bộ nhớ**, được tạo ra dựa trên định nghĩa của lớp. - Mỗi đối tượng có **trạng thái** (state) riêng, tức là giá trị riêng cho từng trường. Trong C#, ta tạo đối tượng bằng từ khóa `new`: ```csharp using System; public class Program { public static void Main() { Car a = new Car(); a.Color = "Đỏ"; a.Speed = 40; Car b = new Car(); b.Color = "Xanh"; b.Speed = 60; a.Run(); // Xe Đỏ đang chạy với tốc độ 40 km/h. b.Run(); // Xe Xanh đang chạy với tốc độ 60 km/h. } } ``` Hai đối tượng `a` và `b` cùng đến từ lớp `Car`, nhưng mỗi đối tượng có màu và tốc độ riêng. Chúng nằm ở hai vùng nhớ khác nhau và hoạt động độc lập. ## Phân biệt lớp và đối tượng | | Lớp (Class) | Đối tượng (Object) | |---|---|---| | Bản chất | Bản thiết kế, khái niệm trừu tượng | Thực thể cụ thể được tạo ra từ lớp | | Bộ nhớ | Chưa chiếm vùng nhớ cho dữ liệu | Chiếm vùng nhớ riêng | | Số lượng | Viết một lần | Tạo được nhiều đối tượng từ một lớp | | Dữ liệu | Chỉ mô tả có những trường nào | Mỗi đối tượng giữ giá trị cụ thể | | Ví dụ | `Car` | Chiếc xe đỏ `a`, chiếc xe xanh `b` | Hãy nhớ: **lớp là khái niệm, đối tượng là sự hiện thực hóa của khái niệm đó.** ## Hoạt động: Một lớp, hai đối tượng Mô phỏng dưới đây chạy từng dòng một chương trình dùng lớp `Car`. Hãy thao tác theo thứ tự sau, bấm **Bước tiếp** để chạy từng dòng: - Mở tab **Lớp Car và hai đối tượng**. Ở bước đầu, lớp `Car` chỉ mới được viết ra. Nó mô tả mỗi xe có `Color` và `Speed`, còn bộ nhớ vẫn trống vì chưa có chiếc xe nào. - Bước `new Car()` đầu tiên tạo đối tượng `Car#1`. Các trường nhận giá trị mặc định `Color = null` và `Speed = 0`, còn biến `a` giữ đường dẫn tới `Car#1`. Sau đó `a.Color = "Đỏ"` chỉ đổi trường của `Car#1`. - Dòng `new Car()` thứ hai tạo thêm `Car#2`, hoàn toàn tách biệt với `Car#1`, và biến `b` trỏ tới nó. `b.Color = "Xanh"` chỉ đổi `Car#2`, còn `Car#1` vẫn màu Đỏ. - Bước `b.Speed = 60` đặt tốc độ cho `Car#2`. Hãy để ý `Speed` của `Car#1` vẫn là 0. - Hai dòng `Console.WriteLine` in ra `Đỏ` rồi `Xanh`. Bước cuối ghi chú rằng một lớp tạo được nhiều đối tượng, mỗi đối tượng giữ dữ liệu riêng. ``` <iframe src="https://codegym-vn.github.io/programming-course-demos/oop_ooad/doi-tuong-lop-va-dong-goi-encapsulation/gioi-thieu-ve-lop-va-doi-tuong-trong-c-sharp/lop-la-gi-doi-tuong-la-gi/" title="Lớp và Đối tượng" style="border:0;" allowfullscreen></iframe> ``` Điều rút ra: lớp chỉ mô tả "có những gì", còn mỗi đối tượng giữ giá trị cụ thể của riêng nó. Đổi dữ liệu của đối tượng này không làm đổi dữ liệu của đối tượng kia. ## Vì sao lớp và đối tượng quan trọng? - **Trừu tượng hóa:** thay vì nghĩ về hàng trăm dòng mã, ta nghĩ về "một chiếc xe", "một sinh viên", "một đơn hàng". - **Đóng gói:** lớp gom dữ liệu và hành vi liên quan vào một đơn vị. Bài sau sẽ nói sâu hơn về điều này. - **Tái sử dụng:** viết lớp một lần, tạo bao nhiêu đối tượng cũng được. - **Tổ chức mã nguồn:** chương trình được chia theo các loại thực thể của bài toán, nên dự án lớn dễ quản lý hơn. ## Tóm tắt - **Lớp** là bản thiết kế: mô tả có những **trường** và **phương thức** nào. - **Đối tượng** là thể hiện cụ thể của lớp, tồn tại trong bộ nhớ. - Trong C#, ta tạo đối tượng bằng `new`, ví dụ `Car a = new Car();`. - Từ một lớp tạo được nhiều đối tượng, mỗi đối tượng có dữ liệu riêng. - Viết lớp chưa tạo ra đối tượng nào. Đối tượng chỉ xuất hiện khi gọi `new`.
A4: 5 | B4: 2. Đối tượng, Lớp và Đóng gói (Encapsulation) | C4: Giới thiệu về Lớp và Đối tượng trong C# | D4: Tạo và Sử dụng Đối tượng | E4: Bài đọc | F4: Nên làm | G4: Done | H4: new tạo đối tượng; biến lớp chứa tham chiếu, không chứa đối tượng. | I4: 3 tab. Tab Tạo và dùng: new, gán trường, gọi phương thức, in console. Tab Gán tham chiếu: Car b = a; b.Color = "Đen"; in a.Color ra Đen vì a và b cùng trỏ Car#1. Tab null: Car c = null; c.Run(); dừng ở bước báo NullReferenceException (console hiện lỗi màu đỏ). | J4: 1 cột, nhiều tab | K4: oop_ooad/doi-tuong-lop-va-dong-goi-encapsulation/gioi-thieu-ve-lop-va-doi-tuong-trong-c-sharp/tao-va-su-dung-doi-tuong/index.html | L4: https://codegym-vn.github.io/programming-course-demos/oop_ooad/doi-tuong-lop-va-dong-goi-encapsulation/gioi-thieu-ve-lop-va-doi-tuong-trong-c-sharp/tao-va-su-dung-doi-tuong/ | M4: Tab 2 là ý quan trọng nhất, nên để mặc định. | P4: Tạo và Sử dụng Đối tượng Trong bài học trước, bạn đã làm quen với khái niệm Lớp (Class) như một bản thiết kế và Đối tượng (Object) như một thể hiện cụ thể của bản thiết kế đó. Nhưng làm thế nào để chúng ta biến bản thiết kế trừu tượng thành một "thực thể" hoạt động trong chương trình C# của mình? Đó chính là nội dung chúng ta sẽ khám phá trong trang bài đọc này: quy trình tạo (hay còn gọi là khởi tạo) và cách tương tác với các đối tượng. Khởi tạo Đối tượng: Biến Bản thiết kế thành Hiện thực Khi bạn định nghĩa một Lớp, bạn chỉ mới tạo ra một khuôn mẫu hoặc một kiểu dữ liệu tùy chỉnh. Lớp đó tự nó không chiếm bộ nhớ hoặc thực hiện bất kỳ hành động nào. Để sử dụng Lớp, bạn cần tạo ra một hoặc nhiều đối tượng từ Lớp đó. Quá trình này được gọi là khởi tạo đối tượng (object instantiation). Mỗi đối tượng được tạo ra là một thể hiện (instance) độc lập của lớp, có bộ nhớ riêng và có thể chứa các giá trị dữ liệu riêng biệt. Hãy hình dung bạn có bản thiết kế cho một ngôi nhà (lớp House). Để có một ngôi nhà thực tế, bạn cần xây dựng nó. Mỗi ngôi nhà được xây dựng từ bản thiết kế đó là một đối tượng House cụ thể, có thể có màu sơn khác nhau, số phòng khác nhau, dù chúng đều tuân theo cùng một cấu trúc cơ bản từ bản thiết kế. Sử dụng từ khóa new và Hàm tạo (Constructor) Trong C#, việc khởi tạo một đối tượng được thực hiện chủ yếu thông qua từ khóa new. Khi bạn sử dụng new, ba việc chính sẽ xảy ra: Cấp phát bộ nhớ: Hệ thống sẽ cấp phát một vùng nhớ trên Heap (khu vực bộ nhớ động) đủ lớn để chứa tất cả các trường (fields) của đối tượng mới. Khởi tạo mặc định: Các trường của đối tượng sẽ được khởi tạo với giá trị mặc định của kiểu dữ liệu tương ứng (ví dụ: 0 cho số nguyên, 0.0 cho số thực, false cho boolean, null cho các kiểu tham chiếu). Gọi Hàm tạo (Constructor): Một phương thức đặc biệt của lớp, được gọi là hàm tạo, sẽ được thực thi. Hàm tạo có nhiệm vụ thiết lập trạng thái ban đầu cho đối tượng, gán các giá trị khởi tạo cho các trường, hoặc thực hiện bất kỳ logic cần thiết nào để đối tượng sẵn sàng sử dụng. Cú pháp cơ bản để tạo một đối tượng là: TenLop tenDoiTuong = new TenLop(); Trong đó: TenLop: Là tên của lớp mà bạn muốn tạo đối tượng. tenDoiTuong: Là tên của biến tham chiếu sẽ "chứa" địa chỉ của đối tượng mới được tạo ra. new TenLop(): Là biểu thức thực hiện việc cấp phát bộ nhớ và gọi hàm tạo của TenLop. Ví dụ: Giả sử chúng ta có một lớp Student đơn giản: public class Student { public string Name; public int Age; // Đây là một hàm tạo (constructor) mặc định // Nếu bạn không định nghĩa, C# sẽ tự động cung cấp một cái. public Student() { Console.WriteLine("Một đối tượng Student mới đã được tạo!"); } } Để tạo một đối tượng Student từ lớp này, bạn sẽ làm như sau: // Khai báo một biến tham chiếu kiểu Student Student student1; // Sử dụng từ khóa 'new' để tạo một đối tượng Student và gán địa chỉ của nó cho student1 student1 = new Student(); // Hoặc kết hợp cả khai báo và khởi tạo trong một dòng: Student student2 = new Student(); Khi dòng Student student1 = new Student(); được thực thi, C# sẽ cấp phát bộ nhớ cho student1, các trường Name và Age sẽ được khởi tạo mặc định (null và 0), và sau đó hàm tạo Student() sẽ được gọi, in ra thông báo. Biến student1 lúc này không chứa bản thân đối tượng mà chứa tham chiếu (địa chỉ) đến đối tượng Student vừa được tạo trên bộ nhớ Heap. Truy cập các thành phần của Đối tượng với Toán tử Chấm (.) Sau khi một đối tượng đã được tạo, bạn cần cách để tương tác với nó – tức là truy cập và thay đổi dữ liệu của nó (các trường hoặc thuộc tính) hoặc yêu cầu nó thực hiện một hành động (gọi các phương thức). Trong C#, điều này được thực hiện thông qua toán tử chấm (.). Toán tử chấm cho phép bạn "đi vào bên trong" đối tượng để truy cập các thành phần công khai (public members) của nó. 1. Truy cập và thay đổi dữ liệu (Trường/Thuộc tính): Bạn có thể đọc hoặc gán giá trị cho các trường (hoặc thuộc tính, sẽ được học kỹ hơn trong bài về Đóng gói) của đối tượng bằng cách sử dụng toán tử chấm. Cú pháp: tenDoiTuong.tenTruong hoặc tenDoiTuong.TenThuocTinh Ví dụ tiếp nối lớp Student: public class Student { public string Name; public int Age; public Student() { Console.WriteLine("Một đối tượng Student mới đã được tạo!"); } public void DisplayInfo() { Console.WriteLine($"Tên: {Name}, Tuổi: {Age}"); } } // Trong phương thức Main hoặc một nơi nào đó trong chương trình của bạn: Student student1 = new Student(); // Tạo đối tượng // Gán giá trị cho các trường của student1 student1.Name = "Nguyễn Văn A"; student1.Age = 20; // Đọc giá trị từ các trường của student1 Console.WriteLine($"Tên của sinh viên là: {student1.Name}"); // Output: Tên của sinh viên là: Nguyễn Văn A Console.WriteLine($"Tuổi của sinh viên là: {student1.Age}"); // Output: Tuổi của sinh viên là: 20 // Tạo một đối tượng Student khác Student student2 = new Student(); student2.Name = "Trần Thị B"; student2.Age = 22; // student1 và student2 là hai đối tượng độc lập, // có dữ liệu riêng biệt mặc dù cùng được tạo từ lớp Student. Console.WriteLine($"Tên của sinh viên 2 là: {student2.Name}"); // Output: Tên của sinh viên 2 là: Trần Thị B 2. Gọi các phương thức (Methods): Các phương thức định nghĩa hành vi của đối tượng. Bạn gọi một phương thức của đối tượng bằng cách sử dụng toán tử chấm, theo sau là tên phương thức và dấu ngoặc đơn (có thể có hoặc không có đối số). Cú pháp: tenDoiTuong.TenPhuongThuc(doiSo1, doiSo2, ...); Ví dụ tiếp nối: // Tiếp tục từ ví dụ trên: Student student1 = new Student(); student1.Name = "Nguyễn Văn A"; student1.Age = 20; // Gọi phương thức DisplayInfo() của đối tượng student1 student1.DisplayInfo(); // Output: Tên: Nguyễn Văn A, Tuổi: 20 Student student2 = new Student(); student2.Name = "Trần Thị B"; student2.Age = 22; // Gọi phương thức DisplayInfo() của đối tượng student2 student2.DisplayInfo(); // Output: Tên: Trần Thị B, Tuổi: 22 Như bạn thấy, student1.DisplayInfo() và student2.DisplayInfo() đều gọi cùng một phương thức, nhưng vì chúng được gọi trên các đối tượng khác nhau, chúng sẽ hiển thị thông tin riêng của từng đối tượng. Đây là một trong những sức mạnh cốt lõi của lập trình hướng đối tượng: mỗi đối tượng hoạt động độc lập với dữ liệu của chính nó. Việc nắm vững cách tạo và sử dụng đối tượng là bước nền tảng quan trọng nhất để bạn có thể xây dựng các ứng dụng hướng đối tượng mạnh mẽ và linh hoạt trong C#. Trong các bài học tiếp theo, chúng ta sẽ đi sâu vào cách định nghĩa lớp một cách chi tiết hơn, bao gồm các loại thành phần khác nhau và cách kiểm soát quyền truy cập để bảo vệ dữ liệu. | Q4: # Tạo và Sử dụng Đối tượng ## Mục tiêu học tập Sau bài học này, bạn có thể: - Tạo đối tượng từ một lớp bằng từ khóa `new` và giải thích `new` làm những việc gì. - Dùng toán tử chấm (`.`) để gán trường và gọi phương thức của đối tượng. - Giải thích biến kiểu lớp chứa **tham chiếu** (reference) tới đối tượng, không chứa bản thân đối tượng. - Nhận ra khi gán `b = a` thì hai biến cùng trỏ tới một đối tượng. - Nhận ra lỗi `NullReferenceException` khi dùng biến đang là `null`. - Quan sát từng bước chạy qua ba tình huống trong hoạt động mô phỏng. ## Khởi tạo đối tượng Khi viết một lớp, ta mới tạo ra một bản thiết kế. Lớp tự nó không chiếm bộ nhớ cho dữ liệu và không làm gì cả. Muốn dùng, ta phải tạo **đối tượng** từ lớp. Việc này gọi là **khởi tạo đối tượng** (object instantiation). Mỗi đối tượng là một **thể hiện** (instance) độc lập, có vùng nhớ riêng và dữ liệu riêng. Trong bài này ta dùng lớp `Dog` (con chó) có trường `Name` và phương thức `Bark()`: ```csharp using System; public class Dog { public string Name; public void Bark() { string s = Name + ": Gâu!"; Console.WriteLine(s); } } ``` ### Từ khóa `new` Cú pháp tạo đối tượng: ```csharp Dog d = new Dog(); ``` Trong đó: - `Dog` (bên trái): kiểu của biến, tức tên lớp. - `d`: tên **biến tham chiếu**, nơi giữ "đường dẫn" tới đối tượng. - `new Dog()`: biểu thức tạo ra đối tượng mới. Khi chạy `new`, C# làm ba việc: 1. **Cấp phát bộ nhớ** trên vùng nhớ **heap** đủ chỗ cho các trường của đối tượng. 2. **Đặt giá trị mặc định** cho các trường: `0` cho số nguyên, `false` cho `bool`, `null` cho kiểu tham chiếu như `string`. 3. **Gọi hàm tạo** (constructor), một phương thức đặc biệt thiết lập trạng thái ban đầu. Nếu bạn không viết, C# tự cung cấp hàm tạo mặc định không làm gì thêm. Hàm tạo sẽ được học kỹ ở bài sau. Ở bài này, ta chỉ cần nhớ `new Dog()` luôn cho ra một đối tượng mới. ## Biến giữ tham chiếu, không giữ đối tượng Đây là điểm dễ nhầm nhất. Với kiểu lớp, biến `d` **không chứa** đối tượng `Dog`. Đối tượng nằm ở heap, còn `d` chỉ giữ **tham chiếu** (đường dẫn) tới nó. Hãy hình dung biến là một tấm danh thiếp ghi địa chỉ, còn đối tượng là căn nhà ở địa chỉ đó. Hệ quả: - Hai biến có thể cùng trỏ tới một đối tượng. - Một biến có thể không trỏ tới đối tượng nào, khi đó giá trị của nó là `null`. ## Dùng đối tượng với toán tử chấm Sau khi có đối tượng, ta dùng **toán tử chấm** (`.`) để "đi vào" bên trong nó. Dấu chấm đọc là "của đối tượng mà biến này trỏ tới". - Gán hoặc đọc trường: `tenBien.TenTruong` - Gọi phương thức: `tenBien.TenPhuongThuc(...)` ```csharp using System; public class Program { public static void Main() { Dog d = new Dog(); // tạo đối tượng, Name đang là null d.Name = "Lu"; // gán trường Name của đối tượng d trỏ tới d.Bark(); // Lu: Gâu! } } ``` Ba bước dùng đối tượng là: tạo bằng `new`, gán dữ liệu qua dấu chấm, gọi phương thức qua dấu chấm. Trong `Bark()`, `Name` là `Name` của chính đối tượng đang được gọi. ## Gán một biến đối tượng cho biến khác Điều gì xảy ra với `Dog b = a;`? Vì **không có `new`**, nên không có đối tượng mới nào được tạo. Biến `b` chỉ chép tham chiếu của `a`. Từ lúc này `a` và `b` cùng trỏ tới một con chó: ```csharp Dog a = new Dog(); a.Name = "Lu"; Dog b = a; // chép tham chiếu, không tạo chó mới b.Name = "Mực"; Console.WriteLine(a.Name); // Mực ``` Đổi tên qua `b` cũng là đổi tên của đối tượng mà `a` đang trỏ tới, nên `a.Name` in ra `Mực`. Muốn có con chó thứ hai thật sự, bạn phải dùng `new Dog()` một lần nữa. ## Biến `null` và NullReferenceException Biến kiểu lớp có thể mang giá trị `null`, nghĩa là chưa trỏ tới đối tượng nào. Nếu dùng dấu chấm trên biến `null`, chương trình không biết đối tượng nào để làm việc và dừng với lỗi: ```csharp Dog c = null; c.Bark(); // System.NullReferenceException: // Object reference not set to an instance of an object. ``` Cách tránh: luôn tạo đối tượng bằng `new` trước khi dùng dấu chấm, hoặc kiểm tra `c != null` khi chưa chắc biến đã trỏ tới đối tượng. ## Hoạt động: Tạo, gán tham chiếu và null Mô phỏng dưới đây có ba tab, dùng lớp `Dog` ở trên. Hãy thao tác theo thứ tự sau, bấm **Bước tiếp** để chạy từng dòng: - Mở tab **Tạo và dùng**. `new Dog()` tạo đối tượng `Dog#1` với `Name` là `null`, biến `d` trỏ tới nó. Sau `d.Name = "Lu"`, dòng `d.Bark()` nhảy vào thân `Bark()` và in `Lu: Gâu!`. - Chuyển sang tab **Gán tham chiếu**. Sau khi tạo `Dog#1` và đặt tên `Lu`, dòng `Dog b = a;` không tạo đối tượng mới. Ở vùng biến, `a` và `b` cùng trỏ tới `Dog#1`. Bước `b.Name = "Mực"` đổi chính `Dog#1`, nên `Console.WriteLine(a.Name)` in ra `Mực`, không phải `Lu`. - Mở tab **Biến null**. Dòng `Dog c = null;` cho `c` giá trị `null`, trong heap chưa có `Dog` nào. Dòng `c.Bark();` làm console hiện lỗi màu đỏ `System.NullReferenceException` và chương trình dừng. ``` <iframe src="https://codegym-vn.github.io/programming-course-demos/oop_ooad/doi-tuong-lop-va-dong-goi-encapsulation/gioi-thieu-ve-lop-va-doi-tuong-trong-c-sharp/tao-va-su-dung-doi-tuong/" title="Tạo và Sử dụng Đối tượng" style="border:0;" allowfullscreen></iframe> ``` Điều rút ra: biến kiểu lớp chỉ giữ tham chiếu tới đối tượng. Gán biến này cho biến khác chỉ chép tham chiếu, nên sửa qua biến nào cũng thấy ở biến kia. Biến `null` thì chưa có đối tượng để dùng. ## Tóm tắt - Viết lớp chưa tạo đối tượng. Dùng `new TenLop()` để tạo đối tượng mới trên heap. - `new` cấp phát bộ nhớ, đặt giá trị mặc định cho trường, rồi gọi hàm tạo. - Dùng toán tử chấm `.` để gán trường và gọi phương thức của đối tượng. - Biến kiểu lớp giữ **tham chiếu**. `Dog b = a;` chỉ chép tham chiếu, `a` và `b` cùng trỏ một đối tượng. - Biến `null` chưa trỏ tới đối tượng nào. Dùng dấu chấm trên nó gây `NullReferenceException`.
