Workbook

Sheet Tong quan
A1: Phân tích hoạt động mô phỏng – Khóa C# Ứng dụng
A2: Danh sách 61 học liệu cần có hoạt động mô phỏng (đã loại các học liệu không cần: lý thuyết, tóm tắt, trùng ý, bài tập nộp, thảo luận, trắc nghiệm).
A4: Chương | B4: Nên làm | C4: Làm thêm nếu muốn | D4: Tổng học liệu | E4: Đã duyệt OK | F4: Done | G4: Chưa done
A5: 1. Cấu trúc dữ liệu nâng cao: Collections | B5: =COUNTIFS('Phan tich'!$B$2:$B$61,$A5,'Phan tich'!$F$2:$F$61,"Nên làm") | C5: =COUNTIFS('Phan tich'!$B$2:$B$61,$A5,'Phan tich'!$F$2:$F$61,"Làm thêm nếu muốn") | D5: =COUNTIF('Phan tich'!$B$2:$B$61,$A5) | E5: =COUNTIFS('Phan tich'!$B$2:$B$61,$A5,'Phan tich'!$T$2:$T$61,"OK") | F5: =COUNTIFS('Phan tich'!$B$2:$B$61,$A5,'Phan tich'!$G$2:$G$61,"Done") | G5: =COUNTIFS('Phan tich'!$B$2:$B$61,$A5,'Phan tich'!$G$2:$G$61,"Chưa done")
A6: 2. Xử lý lỗi và Ngoại lệ (Exception Handling) Cơ bản | B6: =COUNTIFS('Phan tich'!$B$2:$B$61,$A6,'Phan tich'!$F$2:$F$61,"Nên làm") | C6: =COUNTIFS('Phan tich'!$B$2:$B$61,$A6,'Phan tich'!$F$2:$F$61,"Làm thêm nếu muốn") | D6: =COUNTIF('Phan tich'!$B$2:$B$61,$A6) | E6: =COUNTIFS('Phan tich'!$B$2:$B$61,$A6,'Phan tich'!$T$2:$T$61,"OK") | F6: =COUNTIFS('Phan tich'!$B$2:$B$61,$A6,'Phan tich'!$G$2:$G$61,"Done") | G6: =COUNTIFS('Phan tich'!$B$2:$B$61,$A6,'Phan tich'!$G$2:$G$61,"Chưa done")
A7: 3. Xử lý lỗi và Ngoại lệ (Exception Handling) Nâng cao | B7: =COUNTIFS('Phan tich'!$B$2:$B$61,$A7,'Phan tich'!$F$2:$F$61,"Nên làm") | C7: =COUNTIFS('Phan tich'!$B$2:$B$61,$A7,'Phan tich'!$F$2:$F$61,"Làm thêm nếu muốn") | D7: =COUNTIF('Phan tich'!$B$2:$B$61,$A7) | E7: =COUNTIFS('Phan tich'!$B$2:$B$61,$A7,'Phan tich'!$T$2:$T$61,"OK") | F7: =COUNTIFS('Phan tich'!$B$2:$B$61,$A7,'Phan tich'!$G$2:$G$61,"Done") | G7: =COUNTIFS('Phan tich'!$B$2:$B$61,$A7,'Phan tich'!$G$2:$G$61,"Chưa done")
A8: 4. Đọc và Ghi File Văn bản | B8: =COUNTIFS('Phan tich'!$B$2:$B$61,$A8,'Phan tich'!$F$2:$F$61,"Nên làm") | C8: =COUNTIFS('Phan tich'!$B$2:$B$61,$A8,'Phan tich'!$F$2:$F$61,"Làm thêm nếu muốn") | D8: =COUNTIF('Phan tich'!$B$2:$B$61,$A8) | E8: =COUNTIFS('Phan tich'!$B$2:$B$61,$A8,'Phan tich'!$T$2:$T$61,"OK") | F8: =COUNTIFS('Phan tich'!$B$2:$B$61,$A8,'Phan tich'!$G$2:$G$61,"Done") | G8: =COUNTIFS('Phan tich'!$B$2:$B$61,$A8,'Phan tich'!$G$2:$G$61,"Chưa done")
A9: 5. Làm việc với Dữ liệu có Cấu trúc (CSV) | B9: =COUNTIFS('Phan tich'!$B$2:$B$61,$A9,'Phan tich'!$F$2:$F$61,"Nên làm") | C9: =COUNTIFS('Phan tich'!$B$2:$B$61,$A9,'Phan tich'!$F$2:$F$61,"Làm thêm nếu muốn") | D9: =COUNTIF('Phan tich'!$B$2:$B$61,$A9) | E9: =COUNTIFS('Phan tich'!$B$2:$B$61,$A9,'Phan tich'!$T$2:$T$61,"OK") | F9: =COUNTIFS('Phan tich'!$B$2:$B$61,$A9,'Phan tich'!$G$2:$G$61,"Done") | G9: =COUNTIFS('Phan tich'!$B$2:$B$61,$A9,'Phan tich'!$G$2:$G$61,"Chưa done")
A10: 6. Lưu trữ Đối tượng với Serialization | B10: =COUNTIFS('Phan tich'!$B$2:$B$61,$A10,'Phan tich'!$F$2:$F$61,"Nên làm") | C10: =COUNTIFS('Phan tich'!$B$2:$B$61,$A10,'Phan tich'!$F$2:$F$61,"Làm thêm nếu muốn") | D10: =COUNTIF('Phan tich'!$B$2:$B$61,$A10) | E10: =COUNTIFS('Phan tich'!$B$2:$B$61,$A10,'Phan tich'!$T$2:$T$61,"OK") | F10: =COUNTIFS('Phan tich'!$B$2:$B$61,$A10,'Phan tich'!$G$2:$G$61,"Done") | G10: =COUNTIFS('Phan tich'!$B$2:$B$61,$A10,'Phan tich'!$G$2:$G$61,"Chưa done")
A11: Tổng | B11: =SUM(B5:B10) | C11: =SUM(C5:C10) | D11: =SUM(D5:D10) | E11: =SUM(E5:E10) | F11: =SUM(F5:F10) | G11: =SUM(G5:G10)
A13: Cách đọc file
A14: Nên làm | B14: Bài đọc có quá trình chạy hoặc hiện tượng khó hình dung bằng chữ (dịch chuyển phần tử, luồng exception, bộ đệm tệp, phân tích CSV...).
A15: Làm thêm nếu muốn | B15: Có ích nhưng ý chính đã được bài khác hoặc bài đọc truyền tải khá tốt.
A16: Sheet 'Phan tich' | B16: Mỗi dòng một học liệu. Các cột từ 'Mục tiêu' tới 'Lưu ý kiến thức C#' là bản mô tả chi tiết để viết mô phỏng. Ô vàng cuối dòng để bạn chọn OK / Sửa / Bỏ và ghi ý kiến.
A17: Sheet 'Thu vien hinh' | B17: 22 thành phần hình minh họa dùng chung (mã H01–H22). Mỗi mô phỏng kết hợp khung code quen thuộc với 1–3 thành phần hình để đa dạng và trực quan hơn khóa trước.
A19: Nguyên tắc thiết kế
A20: Đơn giản trước | B20: Mỗi mô phỏng một ý chính, 4–9 bước mỗi tab, chỉ bấm Bước tiếp / Chạy hết / Làm lại. Không quiz, không thử thách. Tab chỉ để đổi tình huống.
A21: Hình minh họa | B21: Ngoài khung Mã nguồn – Console – Bộ nhớ, thêm khung 'Hình minh họa' vẽ bằng HTML/SVG thuần (không thư viện ngoài). Chuyển động nhẹ 200–300 ms; tắt chuyển động khi người dùng bật prefers-reduced-motion.
A22: Màu sắc thống nhất | B22: Vàng = đang xét; Xanh lá = thành công/đã xong; Đỏ = lỗi/mất dữ liệu; Xám = bị bỏ qua/không chạy. Có chế độ tối.
A23: Điện thoại | B23: Hiển thị tốt ở bề rộng 390px: hai cột xếp chồng, hình tự co, không tràn ngang.
A24: Sự thật kỹ thuật | B24: Thông điệp lỗi, mã lỗi biên dịch, số byte, kết quả tính toán phải đúng theo .NET hiện đại; tính bằng code thật trong mô phỏng, không bịa.
A25: Lưu ý nội dung lỗi thời | B25: Chương 6 dùng BinaryFormatter/ISerializable: đã bị loại bỏ trong .NET 9. Mô phỏng không minh họa BinaryFormatter; đề xuất cập nhật học liệu.
A26: Thư mục | B26: c-sharp-ung-dung/<chuong>/<bai-hoc>/<hoc-lieu>/index.html, đẩy lên GitHub Pages như các khóa trước.

Sheet Phan tich
A1: STT | B1: Chương (Module) | C1: Bài học (Lesson) | D1: Học liệu (Activity) | E1: Loại học liệu | F1: Mức đề xuất | G1: Trạng thái | H1: Mục tiêu của mô phỏng | I1: Dạng giao diện | J1: Hình minh họa | K1: Thành phần hình (mã) | L1: Tab / tình huống | M1: Kịch bản từng bước | N1: Dữ liệu mẫu | O1: Điểm chốt (bước cuối) | P1: Lưu ý kiến thức C# | Q1: Đường dẫn file (đề xuất) | R1: Link GitHub Pages (sau khi đẩy) | S1: Ghi chú / lý do | T1: Duyệt (OK / Sửa / Bỏ) | U1: Ý kiến của bạn | V1: Nội dung cũ | W1: Nội dung mới
A2: 1 | B2: 1. Cấu trúc dữ liệu nâng cao: Collections | C2: Giới thiệu về Collections và List<T> cơ bản | D2: Giới thiệu Collections trong C# | E2: Bài đọc | F2: Nên làm | G2: Done | H2: Thấy vì sao cần List<T>: mảng có kích thước cố định, còn List<T> tự mở rộng khi thêm phần tử. | I2: 2 cột song song: Mảng int[] | List<int> | J2: Mỗi cột một dãy ô có chỉ số. Ô dự phòng của List vẽ nét đứt. Khi mảng bị ghi quá giới hạn, ô 'không tồn tại' nháy đỏ. Khi List hết chỗ, hiện hiệu ứng cấp dãy ô mới gấp đôi và chép phần tử sang. | K2: H01, H03, H22 | L2: 1 tab: Thêm phần tử thứ 4 và thứ 5 | M2: Hai cột cùng cần lưu điểm 8, 6, 9. Trái: int[] a = new int[3]. Phải: List<int> l = new List<int>() (Count 0, Capacity 0). Trái gán a[0..2]. Phải gọi Add 3 lần: Count 1→3, lần Add đầu cấp sẵn 4 chỗ (Capacity 4, ô thứ 4 nét đứt). Cả hai muốn thêm điểm 7. Trái: a[3] = 7 → không có ô chỉ số 3, console hiện IndexOutOfRangeException, chương trình dừng. Phải: l.Add(7) → lấp ô dự phòng, Count 4, Capacity 4. Phải: l.Add(10) → hết chỗ, List cấp dãy mới 8 ô, chép 4 phần tử sang rồi thêm 10 (Count 5, Capacity 8). Xong: so sánh hai cột. | N2: Điểm: 8, 6, 9, 7, 10 | O2: Mảng cố định kích thước khi tạo. List<T> tự lo việc mở rộng, người dùng chỉ cần gọi Add. | P2: new List<int>() có Capacity 0; lần Add đầu cấp 4, sau đó nhân đôi (chi tiết cài đặt của .NET, chỉ nêu để minh họa). Ghi ngoài mảng ném IndexOutOfRangeException. | Q2: c-sharp-ung-dung/cau-truc-du-lieu-nang-cao-collections/gioi-thieu-ve-collections-va-list-t-co-ban/gioi-thieu-collections-trong-c-sharp/index.html | R2: https://codegym-vn.github.io/programming-course-demos/c-sharp-ung-dung/cau-truc-du-lieu-nang-cao-collections/gioi-thieu-ve-collections-va-list-t-co-ban/gioi-thieu-collections-trong-c-sharp/ | V2: Trong lập trình C#, việc quản lý và thao tác với các nhóm dữ liệu là một nhiệm vụ cơ bản và thường xuyên. Để làm được điều này một cách hiệu quả, .NET Framework cung cấp một tập hợp các cấu trúc dữ liệu mạnh mẽ được gọi là Collections. Collections không chỉ giúp chúng ta lưu trữ dữ liệu mà còn cung cấp các cơ chế linh hoạt để thêm, xóa, truy cập và sắp xếp chúng. Collections là gì và Tại sao cần sử dụng chúng? Một Collection (tập hợp) là một cấu trúc dữ liệu được thiết kế để lưu trữ và quản lý một nhóm các đối tượng. Tưởng tượng bạn có một danh sách các món đồ cần mua, một tập hợp các sinh viên trong lớp, hoặc một bộ sưu tập các bài hát yêu thích. Thay vì khai báo từng biến riêng lẻ cho mỗi món đồ, sinh viên hay bài hát, Collections cho phép bạn nhóm chúng lại thành một đơn vị duy nhất, dễ dàng quản lý hơn. Chúng ta cần sử dụng Collections vì những lý do sau: Quản lý nhóm dữ liệu: Collections cung cấp một cách có tổ chức để lưu trữ và truy cập nhiều phần tử cùng một lúc. Thao tác dữ liệu hiệu quả: Chúng đi kèm với nhiều phương thức tích hợp sẵn để thực hiện các thao tác phổ biến như thêm, xóa, tìm kiếm, sắp xếp các phần tử một cách dễ dàng và hiệu quả. Linh hoạt và tái sử dụng: Collections được thiết kế để hoạt động với nhiều kiểu dữ liệu khác nhau và có thể được tái sử dụng trong nhiều ngữ cảnh lập trình. Ưu điểm của Collections so với Mảng truyền thống Trước khi có Collections, lập trình viên thường sử dụng mảng (Array) để lưu trữ các nhóm dữ liệu. Tuy nhiên, mảng truyền thống trong C# có một số hạn chế đáng kể mà Collections khắc phục được: Kích thước cố định: Khi bạn khai báo một mảng, bạn phải chỉ định kích thước của nó ngay từ đầu. Sau đó, bạn không thể thay đổi kích thước này. Nếu bạn cần thêm phần tử vượt quá giới hạn hoặc xóa nhiều phần tử khiến mảng bị trống, bạn sẽ phải tạo một mảng mới và sao chép tất cả các phần tử, điều này rất tốn kém và không hiệu quả. int[] mangSoNguyen = new int[5]; // Kích thước cố định là 5 // Không thể thêm phần tử thứ 6 mà không tạo mảng mới Ngược lại, hầu hết các Collections đều có kích thước động. Chúng tự động điều chỉnh khả năng lưu trữ khi bạn thêm hoặc xóa phần tử, giúp bạn không cần lo lắng về việc quản lý kích thước thủ công. Thiếu các phương thức tiện ích: Mảng chỉ cung cấp các chức năng cơ bản như truy cập phần tử theo chỉ mục. Để thực hiện các thao tác phức tạp hơn như tìm kiếm một phần tử cụ thể, sắp xếp danh sách, hoặc kiểm tra sự tồn tại của một phần tử, bạn phải tự viết các vòng lặp và thuật toán. Collections cung cấp hàng loạt các phương thức được xây dựng sẵn để thực hiện các tác vụ này, giúp mã của bạn ngắn gọn hơn, dễ đọc hơn và ít lỗi hơn. Ví dụ, bạn có thể gọi một phương thức Sort() để sắp xếp toàn bộ Collection chỉ trong một dòng lệnh. An toàn kiểu (Type Safety): Mặc dù mảng cũng có thể được định kiểu (int[], string[]), nhưng việc sử dụng các mảng kiểu object[] để lưu trữ nhiều kiểu dữ liệu khác nhau có thể dẫn đến các lỗi thời gian chạy (runtime errors) và yêu cầu ép kiểu (casting), gây giảm hiệu suất do boxing/unboxing. Các Collections hiện đại trong .NET Framework (đặc biệt là các generic collections) được thiết kế để đảm bảo an toàn kiểu mà không cần ép kiểu thủ công, giúp phát hiện lỗi ngay tại thời điểm biên dịch và cải thiện hiệu suất. Tóm lại, Collections cung cấp một giải pháp mạnh mẽ và linh hoạt hơn nhiều so với mảng truyền thống, đặc biệt là khi bạn cần quản lý các tập hợp dữ liệu có kích thước thay đổi hoặc cần thực hiện nhiều thao tác phức tạp. Các loại Collection phổ biến trong .NET Framework .NET Framework cung cấp một thư viện phong phú các Collection, mỗi loại được thiết kế để giải quyết các bài toán cụ thể. Dưới đây là một số loại phổ biến nhất mà bạn sẽ thường xuyên gặp trong lập trình C#: List<T>: Đây là một trong những Collection được sử dụng rộng rãi nhất. List<T> đại diện cho một danh sách các đối tượng có thể truy cập theo chỉ mục. Nó có kích thước động, cho phép bạn thêm, xóa và truy cập các phần tử một cách dễ dàng. List<T> lý tưởng cho các tình huống cần lưu trữ một chuỗi các phần tử có thứ tự. Bạn sẽ tìm hiểu sâu hơn về List<T> trong các bài học tiếp theo, bao gồm khái niệm, cách khởi tạo, thêm, truy cập và xóa các phần tử. Dictionary<TKey, TValue>: Collection này lưu trữ dữ liệu dưới dạng các cặp khóa-giá trị (key-value pairs). Mỗi khóa là duy nhất và được sử dụng để truy xuất giá trị tương ứng một cách nhanh chóng. Dictionary<TKey, TValue> rất hữu ích khi bạn cần tìm kiếm dữ liệu dựa trên một định danh duy nhất, giống như một cuốn từ điển nơi mỗi từ (khóa) có một định nghĩa (giá trị). HashSet<T>: HashSet<T> là một tập hợp các phần tử không có thứ tự và không chứa các phần tử trùng lặp. Nó tối ưu cho các thao tác kiểm tra sự tồn tại của một phần tử, hợp nhất (union), giao (intersection) và hiệu (difference) giữa các tập hợp. Queue<T>: Queue<T> (hàng đợi) là một Collection hoạt động theo nguyên tắc "Vào trước, Ra trước" (FIFO - First-In, First-Out). Các phần tử được thêm vào cuối hàng đợi và được lấy ra từ đầu hàng đợi. Tương tự như một hàng người xếp hàng chờ mua vé. Stack<T>: Stack<T> (ngăn xếp) là một Collection hoạt động theo nguyên tắc "Vào sau, Ra trước" (LIFO - Last-In, First-Out). Các phần tử được thêm vào (push) và lấy ra (pop) từ cùng một đầu của ngăn xếp. Tương tự như một chồng đĩa, bạn chỉ có thể thêm hoặc lấy đĩa từ trên cùng. Việc lựa chọn đúng Collection cho bài toán của bạn là một kỹ năng quan trọng, giúp tối ưu hóa hiệu suất và làm cho mã của bạn dễ quản lý hơn. Namespace System.Collections.Generic Hầu hết các Collection phổ biến và mạnh mẽ mà chúng ta vừa thảo luận (như List<T>, Dictionary<TKey, TValue>, HashSet<T>, Queue<T>, Stack<T>) đều thuộc về namespace System.Collections.Generic. Namespace này chứa các generic collections. Từ "generic" (tổng quát) ở đây có nghĩa là các Collection này được thiết kế để hoạt động với bất kỳ kiểu dữ liệu nào mà bạn chỉ định, mà vẫn đảm bảo an toàn kiểu. Ví dụ, khi bạn khai báo List<string>, bạn đang tạo một danh sách chỉ có thể chứa các đối tượng kiểu string. Điều này giúp trình biên dịch kiểm tra lỗi ngay lập tức nếu bạn cố gắng thêm một kiểu dữ liệu khác vào danh sách này, đồng thời tránh được chi phí hiệu suất của việc boxing/unboxing khi làm việc với các kiểu giá trị. Để sử dụng các Collection từ namespace này, bạn cần thêm câu lệnh using vào đầu file mã nguồn của mình: using System; using System.Collections.Generic; // Cần thiết để sử dụng List<T>, Dictionary<TKey, TValue>, v.v. public class ChuongTrinh { public static void Main(string[] args) { List<string> tenSinhVien = new List<string>(); tenSinhVien.Add("Nguyễn Văn A"); tenSinhVien.Add("Trần Thị B"); foreach (string ten in tenSinhVien) { Console.WriteLine(ten); } } } Trong các bài học tiếp theo, chúng ta sẽ đi sâu vào cách làm việc với List<T>, khám phá các phương thức và thuộc tính của nó để bạn có thể tự tin quản lý các tập hợp dữ liệu trong ứng dụng C# của mình. | W2: # Giới thiệu Collections trong C# ## Mục tiêu học tập Sau bài học này, bạn có thể: - Giải thích Collection (tập hợp) là gì và vì sao cần dùng nó. - Nêu hai hạn chế chính của mảng: kích thước cố định và thiếu phương thức tiện ích. - Kể tên các collection phổ biến: `List<T>`, `Dictionary<TKey, TValue>`, `HashSet<T>`, `Queue<T>`, `Stack<T>`. - Nhận ra namespace `System.Collections.Generic` và ý nghĩa của "generic". - Quan sát mảng báo lỗi khi hết chỗ, còn `List<T>` tự mở rộng, bằng hoạt động mô phỏng. ## Collection là gì? Một **Collection** (tập hợp) là một cấu trúc dữ liệu dùng để lưu và quản lý một nhóm đối tượng. Hãy nghĩ đến danh sách đồ cần mua, danh sách sinh viên trong lớp hay danh sách bài hát yêu thích. Thay vì khai báo từng biến riêng lẻ, bạn gom chúng vào một đơn vị duy nhất. Collection giúp bạn: - **Quản lý nhóm dữ liệu** một cách có tổ chức, truy cập nhiều phần tử cùng lúc. - **Thao tác nhanh**: có sẵn các phương thức để thêm, xóa, tìm kiếm, sắp xếp. - **Tái sử dụng**: cùng một collection dùng được cho nhiều kiểu dữ liệu khác nhau. ## Vì sao không chỉ dùng mảng? Bạn đã biết **mảng** (array). Mảng rất tiện, nhưng có hai hạn chế khi dữ liệu thay đổi thường xuyên. **1. Kích thước cố định.** Số ô được quyết định lúc tạo và không đổi được nữa. Muốn thêm phần tử vượt giới hạn, bạn phải tạo mảng mới rồi chép dữ liệu sang. ```csharp int[] a = new int[3]; // đúng 3 ô: chỉ số 0, 1, 2 a[3] = 7; // lỗi lúc chạy: IndexOutOfRangeException ``` **2. Thiếu phương thức tiện ích.** Mảng chủ yếu cho phép đọc và ghi theo chỉ số. Muốn tìm, xóa hay sắp xếp, bạn thường phải tự viết vòng lặp. Collection khắc phục cả hai: hầu hết có **kích thước động** (tự co giãn khi thêm hoặc xóa) và đi kèm nhiều phương thức dựng sẵn. | Tiêu chí | Mảng `int[]` | `List<int>` | |---|---|---| | Kích thước | Cố định lúc tạo | Tự mở rộng khi `Add` | | Số phần tử hiện có | `Length` | `Count` | | Thêm, xóa, tìm, sắp xếp | Tự viết vòng lặp | Có sẵn phương thức | ## Các collection phổ biến | Collection | Ý chính | Hình dung | |---|---|---| | `List<T>` | Danh sách có thứ tự, truy cập theo chỉ số, tự co giãn | Danh sách mua sắm | | `Dictionary<TKey, TValue>` | Lưu cặp khóa - giá trị, tra theo khóa rất nhanh | Từ điển | | `HashSet<T>` | Tập hợp không trùng lặp, không quan tâm thứ tự | Tập hợp trong toán học | | `Queue<T>` | Vào trước, ra trước (FIFO) | Hàng người xếp mua vé | | `Stack<T>` | Vào sau, ra trước (LIFO) | Chồng đĩa | Chọn đúng collection cho bài toán giúp mã gọn hơn và chạy hiệu quả hơn. Các bài sau sẽ đi sâu vào `List<T>` trước, rồi đến `Dictionary<TKey, TValue>`. ## Namespace System.Collections.Generic Các collection trên nằm trong namespace `System.Collections.Generic`. Từ **generic** (tổng quát) nghĩa là collection hoạt động với kiểu dữ liệu do bạn chỉ định trong cặp `< >`, và vẫn **an toàn kiểu** (type safety). Ví dụ `List<string>` chỉ chứa `string`. Nếu bạn thêm một số vào, trình biên dịch báo lỗi ngay, không phải đợi đến lúc chạy. Để dùng, hãy thêm `using` ở đầu file: ```csharp using System; using System.Collections.Generic; public class Program { public static void Main() { List<string> names = new List<string>(); names.Add("Lan"); names.Add("Minh"); foreach (string name in names) { Console.WriteLine(name); } // Lan // Minh } } ``` ## Hoạt động: Mảng cố định và List tự mở rộng Mô phỏng dưới đây có hai cột cùng lưu năm điểm 8, 6, 9, 7, 10. Hãy thao tác theo thứ tự sau, bấm **Bước tiếp** để chạy từng dòng: - Mở tab **Thêm phần tử thứ 4 và thứ 5**. Quan sát **cột trái** (mảng `int[]`). `new int[3]` tạo đúng 3 ô, mỗi ô mang giá trị 0, `Length` là 3. Ba dòng `a[0] = 8`, `a[1] = 6`, `a[2] = 9` lấp đầy 3 ô. Đến `a[3] = 7`, không còn ô số 3, nên thẻ lỗi đỏ **IndexOutOfRangeException** hiện ra với thông báo "Index was outside the bounds of the array." và chương trình dừng. - Nhìn sang **cột phải** (`List<int>`). List mới tạo còn rỗng, `Count` 0 và `Capacity` 0. Lần `Add(8)` đầu tiên, List cấp sẵn 4 chỗ (các ô nét đứt là chỗ còn trống). `Add(6)` và `Add(9)` chỉ đặt vào ô kế tiếp, `Count` lên 3. `Add(7)` lấp ô dự phòng cuối: `Count` 4, `Capacity` 4, List đã đầy. - Với `Add(10)`, List hết chỗ. Hãy xem hình: List cấp một dãy mới gấp đôi (8 ô), chép 4 phần tử sang, dãy cũ mờ đi vì bị bỏ. Sau đó 10 vào ô số 4. Kết quả cuối: `Count` 5, `Capacity` 8, không có lỗi nào. ``` <iframe src="https://codegym-vn.github.io/programming-course-demos/c-sharp-ung-dung/cau-truc-du-lieu-nang-cao-collections/gioi-thieu-ve-collections-va-list-t-co-ban/gioi-thieu-collections-trong-c-sharp/" title="Giới thiệu Collections trong C#" style="border:0;" allowfullscreen></iframe> ``` Điều rút ra: mảng có kích thước cố định nên thêm phần tử thứ 4 vào mảng 3 ô là lỗi. `List<T>` tự cấp thêm chỗ khi cần, bạn chỉ việc gọi `Add`. Việc nhân đôi `Capacity` (4 rồi 8) là chi tiết cài đặt của .NET, chỉ nêu để bạn hình dung. ## Tóm tắt - **Collection** là cấu trúc dữ liệu để lưu và quản lý một nhóm đối tượng. - Mảng có kích thước cố định và ít phương thức tiện ích. Collection thường có kích thước động và nhiều phương thức dựng sẵn. - Các collection phổ biến: `List<T>`, `Dictionary<TKey, TValue>`, `HashSet<T>`, `Queue<T>`, `Stack<T>`. - Chúng nằm trong `System.Collections.Generic`. "Generic" nghĩa là chỉ định kiểu dữ liệu và được kiểm tra kiểu ngay lúc biên dịch. - `List<T>` tự mở rộng khi `Add`, còn mảng thì báo `IndexOutOfRangeException` khi vượt kích thước.
A3: 2 | B3: 1. Cấu trúc dữ liệu nâng cao: Collections | C3: Giới thiệu về Collections và List<T> cơ bản | D3: Khái niệm và Khởi tạo List<T> | E3: Bài đọc | F3: Nên làm | G3: Done | H3: Phân biệt 4 cách khởi tạo List<T> và hiểu Count (số phần tử thật) khác Capacity (chỗ đã chuẩn bị). | I3: 1 cột, 4 tab | J3: Dãy ô List với ô dự phòng nét đứt; hai ô biến lớn Count và Capacity. Tab 'Từ mảng' đặt dãy ô mảng và dãy ô List cạnh nhau để thấy là hai bản riêng. | K3: H01 | L3: Rỗng | Có sức chứa ban đầu | Khởi tạo kèm giá trị | Từ mảng có sẵn | M3: Tab Rỗng: new List<string>() → Count 0, Capacity 0; Add("An") → Count 1, Capacity 4. Tab Sức chứa: new List<string>(10) → 10 ô nét đứt, Count vẫn 0. Thử names[0] khi chưa Add → ArgumentOutOfRangeException: Capacity không phải số phần tử. Tab Kèm giá trị: new List<string> { "An", "Bình", "Chi" } → mô phỏng cho thấy trình biên dịch gọi Add 3 lần. Tab Từ mảng: int[] arr = {1, 2, 3}; var list = new List<int>(arr) → dữ liệu được chép. Đổi arr[0] = 99, list[0] vẫn là 1. Bước cuối mỗi tab: ghi chú Count và Capacity. | N3: Tên: An, Bình, Chi; mảng {1, 2, 3} | O3: Count là số phần tử đang có; Capacity là chỗ đã cấp sẵn. Chỉ truy cập được chỉ số 0 đến Count − 1. | P3: list[i] với i ≥ Count ném ArgumentOutOfRangeException (khác mảng: IndexOutOfRangeException). Collection initializer thực chất gọi Add. | Q3: c-sharp-ung-dung/cau-truc-du-lieu-nang-cao-collections/gioi-thieu-ve-collections-va-list-t-co-ban/khai-niem-va-khoi-tao-list-t/index.html | R3: https://codegym-vn.github.io/programming-course-demos/c-sharp-ung-dung/cau-truc-du-lieu-nang-cao-collections/gioi-thieu-ve-collections-va-list-t-co-ban/khai-niem-va-khoi-tao-list-t/ | V3: List<T> là gì? Trong lập trình C#, khi bạn cần quản lý một tập hợp các đối tượng cùng kiểu, List<T> là một trong những cấu trúc dữ liệu mạnh mẽ và được sử dụng phổ biến nhất. List<T> là một lớp thuộc không gian tên System.Collections.Generic, đại diện cho một danh sách các đối tượng được nhập mạnh (strongly typed) có thể được truy cập bằng chỉ mục. Chữ T trong List<T> là một tham số kiểu (type parameter), cho phép bạn chỉ định kiểu dữ liệu mà danh sách sẽ chứa. Các đặc điểm nổi bật của List<T>: Kích thước động: Không giống như mảng (Array) có kích thước cố định, List<T> có thể tự động co giãn khi bạn thêm hoặc xóa phần tử. Điều này giúp bạn linh hoạt hơn rất nhiều trong việc quản lý dữ liệu mà không cần phải lo lắng về việc cấp phát lại bộ nhớ thủ công. Được nhập mạnh (Strongly Typed): Khi bạn khai báo một List<T> (ví dụ: List<int>, List<string>), danh sách đó chỉ có thể chứa các phần tử thuộc kiểu T đã được chỉ định. Điều này giúp phát hiện lỗi kiểu dữ liệu ngay tại thời điểm biên dịch, tăng cường tính an toàn và dễ bảo trì của mã nguồn. Có thứ tự: Các phần tử trong List<T> được duy trì theo thứ tự chúng được thêm vào và có thể được truy cập thông qua chỉ mục (index) bắt đầu từ 0. Cung cấp nhiều phương thức tiện ích:List<T> đi kèm với rất nhiều phương thức dựng sẵn để thêm, xóa, tìm kiếm, sắp xếp và thao tác với các phần tử một cách dễ dàng. So sánh List<T> với Mảng (Array) Mặc dù cả List<T> và mảng đều có thể lưu trữ một tập hợp các phần tử cùng kiểu và truy cập bằng chỉ mục, chúng có những khác biệt cơ bản: Trong hầu hết các trường hợp ứng dụng thực tế, List<T> là lựa chọn ưu tiên khi bạn cần một danh sách linh hoạt và dễ thao tác. Khai báo và Khởi tạo List<T> rỗng Để sử dụng List<T>, trước tiên bạn cần khai báo một biến kiểu List<T> và sau đó khởi tạo một đối tượng List<T> mới. Cú pháp cơ bản để khai báo và khởi tạo một List<T> rỗng là: List<T> tenBienDanhSach = new List<T>(); Trong đó: T là kiểu dữ liệu của các phần tử mà danh sách sẽ chứa (ví dụ: int, string, double, hoặc một kiểu đối tượng tùy chỉnh). tenBienDanhSach là tên mà bạn đặt cho biến danh sách của mình. Ví dụ: // Khai báo và khởi tạo một List rỗng chứa các số nguyên List<int> danhSachSoNguyen = new List<int>(); // Khai báo và khởi tạo một List rỗng chứa các chuỗi List<string> danhSachTen = new List<string>(); // Khai báo và khởi tạo một List rỗng chứa các số thập phân List<double> danhSachDiem = new List<double>(); // Bạn có thể kiểm tra số lượng phần tử hiện có bằng thuộc tính Count Console.WriteLine($"Số lượng số nguyên: {danhSachSoNguyen.Count}"); // Kết quả: 0 Console.WriteLine($"Số lượng tên: {danhSachTen.Count}"); // Kết quả: 0 Khi bạn khởi tạo một List<T> rỗng bằng new List<T>(), nó sẽ tạo ra một danh sách trống. Bạn có thể bắt đầu thêm các phần tử vào danh sách này sau đó (các phương thức thêm phần tử sẽ được tìm hiểu chi tiết trong bài học tiếp theo). Khởi tạo với dung lượng ban đầu (Capacity) Mặc dù List<T> có kích thước động, bạn có thể tùy chọn cung cấp một dung lượng ban đầu (initial capacity) cho danh sách khi khởi tạo. Điều này hữu ích khi bạn biết trước (hoặc ước tính) số lượng phần tử mà danh sách sẽ chứa, giúp tối ưu hiệu suất bằng cách tránh các hoạt động cấp phát lại bộ nhớ không cần thiết khi danh sách mở rộng. // Khởi tạo một List<string> rỗng với dung lượng ban đầu là 10 phần tử List<string> danhSachMonHoc = new List<string>(10); Console.WriteLine($"Dung lượng ban đầu của danh sách môn học: {danhSachMonHoc.Capacity}"); // Kết quả: 10 Console.WriteLine($"Số lượng phần tử trong danh sách môn học: {danhSachMonHoc.Count}"); // Kết quả: 0 (vẫn rỗng) Lưu ý rằng Capacity (dung lượng) khác với Count (số lượng phần tử). Capacity là số lượng phần tử mà List<T> có thể chứa trước khi cần phải cấp phát lại bộ nhớ bên trong, trong khi Count là số lượng phần tử thực tế đang có trong danh sách. Khởi tạo List<T> với các phần tử ban đầu (Collection Initializer) C# cung cấp một cú pháp tiện lợi gọi là Collection Initializer (bộ khởi tạo tập hợp) để khởi tạo một List<T> và điền các phần tử vào nó ngay lập tức. Điều này giúp mã nguồn của bạn trở nên gọn gàng và dễ đọc hơn. Cú pháp sử dụng dấu ngoặc nhọn {} ngay sau lệnh khởi tạo new List<T>(), với các phần tử được phân tách bằng dấu phẩy: List<T> tenBienDanhSach = new List<T> { phanTu1, phanTu2, // ... phanTuN }; Ví dụ: // Khởi tạo List<string> với các tên học sinh ban đầu List<string> hocSinhs = new List<string> { "Nguyễn Văn A", "Trần Thị B", "Lê Hoàng C", "Phạm Minh D" }; Console.WriteLine($"Số lượng học sinh: {hocSinhs.Count}"); // Kết quả: 4 // Khởi tạo List<int> với các số chẵn ban đầu List<int> soChan = new List<int> { 2, 4, 6, 8, 10 }; Console.WriteLine($"Số lượng số chẵn: {soChan.Count}"); // Kết quả: 5 Collection Initializer là một cách rất hiệu quả để tạo ra một danh sách với dữ liệu ban đầu, đặc biệt khi bạn có một tập hợp các phần tử cố định hoặc đã biết trước. Các loại dữ liệu có thể lưu trữ trong List<T> Vì List<T> là một cấu trúc dữ liệu generic và được nhập mạnh, bạn có thể tạo danh sách chứa hầu hết mọi kiểu dữ liệu trong C#. 1. Kiểu dữ liệu nguyên thủy (Primitive Types) và Kiểu cấu trúc (Structs) Bạn có thể lưu trữ các kiểu dữ liệu cơ bản như số nguyên, số thực, ký tự, boolean, hoặc các kiểu cấu trúc (struct) tùy chỉnh. // List chứa số nguyên (int) List<int> danhSachTuoi = new List<int> { 25, 30, 22, 45 }; // List chứa số thực (double) List<double> danhSachGia = new List<double> { 19.99, 5.50, 120.00 }; // List chứa ký tự (char) List<char> danhSachKyTu = new List<char> { 'a', 'b', 'c', 'd' }; // List chứa boolean List<bool> danhSachTrangThai = new List<bool> { true, false, true }; 2. Kiểu dữ liệu tham chiếu (Reference Types) List<T> cũng rất mạnh mẽ khi làm việc với các kiểu dữ liệu tham chiếu, bao gồm string và các đối tượng của lớp (class) do bạn tự định nghĩa. // List chứa chuỗi (string) List<string> danhSachTenQuocGia = new List<string> { "Việt Nam", "Mỹ", "Nhật Bản", "Hàn Quốc" }; // Ví dụ với một lớp tùy chỉnh (giả định có lớp SinhVien) public class SinhVien { public int MaSV { get; set; } public string TenSV { get; set; } public SinhVien(int maSV, string tenSV) { MaSV = maSV; TenSV = tenSV; } } // List chứa các đối tượng SinhVien List<SinhVien> danhSachSinhVien = new List<SinhVien> { new SinhVien(101, "Nguyễn Văn An"), new SinhVien(102, "Trần Thị Bình"), new SinhVien(103, "Lê Văn Cường") }; Console.WriteLine($"Sinh viên đầu tiên: {danhSachSinhVien[0].TenSV}"); // Kết quả: Nguyễn Văn An 3. List (Lưu trữ các kiểu hỗn hợp) Mặc dù List<T> được thiết kế để nhập mạnh, bạn có thể sử dụng List<object> nếu bạn thực sự cần lưu trữ các phần tử thuộc nhiều kiểu dữ liệu khác nhau trong cùng một danh sách. Tuy nhiên, việc này thường không được khuyến khích vì: Mất an toàn kiểu dữ liệu: Trình biên dịch sẽ không thể kiểm tra kiểu dữ liệu tại thời điểm biên dịch, dẫn đến khả năng xảy ra lỗi InvalidCastException khi bạn cố gắng ép kiểu một đối tượng sai kiểu. Hiệu suất: Đối với các kiểu giá trị (như int, double), việc lưu trữ chúng trong List<object> sẽ gây ra hiện tượng boxing (đóng gói kiểu giá trị vào một đối tượng), và khi truy cập, bạn sẽ phải thực hiện unboxing (giải phóng khỏi đối tượng). Các hoạt động boxing/unboxing có thể làm giảm hiệu suất. Ví dụ về List (Sử dụng cẩn trọng): List<object> danhSachHonHop = new List<object> { 123, // int "Hello World", // string 3.14, // double true, // bool new SinhVien(201, "Dương Thị E") // Đối tượng tùy chỉnh }; // Cần ép kiểu rõ ràng và kiểm tra kiểu trước khi sử dụng if (danhSachHonHop[0] is int soNguyen) { Console.WriteLine($"Phần tử đầu tiên là số nguyên: {soNguyen}"); } // Nếu không kiểm tra, có thể gặp lỗi ép kiểu // string ten = (string)danhSachHonHop[0]; // Sẽ gây lỗi InvalidCastException Trong hầu hết các trường hợp, việc thiết kế mã nguồn của bạn sao cho List<T> chứa các đối tượng cùng một kiểu cụ thể là phương pháp tốt nhất, đảm bảo tính an toàn, dễ bảo trì và hiệu suất cao. Nếu bạn cần lưu trữ dữ liệu hỗn hợp một cách có cấu trúc, hãy cân nhắc sử dụng các kỹ thuật khác như tạo một lớp cơ sở chung, interface, hoặc sử dụng các cấu trúc dữ liệu khác như Dictionary<string, object>. | W3: # Khái niệm và Khởi tạo List<T> ## Mục tiêu học tập Sau bài học này, bạn có thể: - Giải thích `List<T>` là gì và ý nghĩa của tham số kiểu `T`. - Phân biệt `Count` (số phần tử thật) với `Capacity` (chỗ đã cấp sẵn). - Khởi tạo `List<T>` theo bốn cách: rỗng, có sức chứa ban đầu, kèm giá trị, từ mảng có sẵn. - Giải thích vì sao đổi mảng gốc không làm đổi `List<T>` đã tạo từ mảng đó. - Quan sát `Count` và `Capacity` thay đổi ở từng cách khởi tạo bằng hoạt động mô phỏng. ## List<T> là gì? `List<T>` là lớp trong namespace `System.Collections.Generic`, đại diện cho một **danh sách có thứ tự** các phần tử cùng kiểu, truy cập được bằng **chỉ số** (index) bắt đầu từ 0. Chữ `T` là **tham số kiểu** (type parameter): bạn thay nó bằng kiểu dữ liệu muốn lưu, như `List<int>` hay `List<string>`. Đặc điểm nổi bật: - **Kích thước động:** tự co giãn khi thêm hoặc xóa phần tử, khác với mảng. - **Gõ mạnh (strongly typed):** `List<string>` chỉ chứa `string`, lỗi kiểu được báo ngay lúc biên dịch. - **Có thứ tự:** phần tử nằm theo thứ tự được thêm vào. - **Nhiều phương thức sẵn có:** thêm, xóa, tìm, sắp xếp. | Tiêu chí | Mảng | `List<T>` | |---|---|---| | Kích thước | Cố định | Tự thay đổi | | Số phần tử | `Length` | `Count` | | Thêm, xóa | Không có sẵn | `Add`, `Insert`, `Remove`... | Khi cần một danh sách linh hoạt, `List<T>` thường là lựa chọn đầu tiên. ## Count và Capacity Bên trong, `List<T>` giữ một dãy ô. Hai con số cần phân biệt: - **`Count`**: số phần tử đang có thật trong danh sách. - **`Capacity`**: số ô List đã cấp sẵn. Luôn lớn hơn hoặc bằng `Count`. Capacity là chỗ dự phòng để lần `Add` sau không phải cấp thêm bộ nhớ. Bạn chỉ **đọc được các chỉ số từ 0 đến `Count - 1`**, không phải đến `Capacity - 1`. ## Bốn cách khởi tạo ### Cách 1: List rỗng ```csharp using System; using System.Collections.Generic; public class Program { public static void Main() { var names = new List<string>(); Console.WriteLine(names.Count); // 0 Console.WriteLine(names.Capacity); // 0 names.Add("An"); Console.WriteLine(names.Capacity); // 4 (lần Add đầu cấp sẵn 4 chỗ) names.Add("Bình"); Console.WriteLine(names.Count); // 2 Console.WriteLine(names.Capacity); // 4 } } ``` List rỗng có `Count` 0 và `Capacity` 0. Lần `Add` đầu tiên cấp sẵn 4 chỗ. ### Cách 2: Có sức chứa ban đầu Nếu biết trước khoảng bao nhiêu phần tử, bạn truyền số đó vào hàm khởi tạo để tránh phải cấp thêm chỗ về sau: ```csharp var names = new List<string>(10); Console.WriteLine(names.Count); // 0 Console.WriteLine(names.Capacity); // 10 // var x = names[0]; // lỗi: ArgumentOutOfRangeException ``` Mười ô dự phòng **chưa phải phần tử**. List vẫn rỗng, nên đọc `names[0]` sẽ ném `ArgumentOutOfRangeException`. ### Cách 3: Khởi tạo kèm giá trị **Collection initializer** (bộ khởi tạo tập hợp) cho phép liệt kê giá trị trong cặp ngoặc nhọn: ```csharp var names = new List<string> { "An", "Bình", "Chi" }; Console.WriteLine(names.Count); // 3 ``` Trình biên dịch thực chất tạo List rỗng, rồi gọi `Add` cho từng giá trị. Viết gọn hay gọi `Add` từng lần đều cho kết quả giống nhau: `Count` 3, `Capacity` 4. ### Cách 4: Từ mảng có sẵn ```csharp int[] arr = { 1, 2, 3 }; var list = new List<int>(arr); arr[0] = 99; Console.WriteLine(list[0]); // 1 ``` `new List<int>(arr)` **chép** từng phần tử sang một nơi riêng, nên mảng và List là hai bản độc lập. Đổi `arr` sau đó không ảnh hưởng `list`. Lúc này `Count` và `Capacity` đều là 3. ## Hoạt động: Bốn cách tạo List Mô phỏng dưới đây có bốn tab, mỗi tab là một cách khởi tạo. Hãy để ý hai ô **Count** và **Capacity**. Bấm **Bước tiếp** để chạy từng dòng: - Mở tab **Rỗng**. `new List<string>()` cho Count 0 và Capacity 0 (chưa có ô nào). `Add("An")` làm List cấp sẵn 4 chỗ (nét đứt) và đặt "An" vào ô 0: Count 1, Capacity 4. `Add("Bình")` chỉ đặt vào ô kế tiếp: Count 2, Capacity vẫn 4. - Mở tab **Có sức chứa ban đầu**. `new List<string>(10)` hiện 10 ô nét đứt nhưng Count vẫn 0. Dòng `names[0]` làm thẻ lỗi đỏ **ArgumentOutOfRangeException** xuất hiện, vì chưa có phần tử nào. - Mở tab **Khởi tạo kèm giá trị**. List rỗng được tạo trước, rồi "An", "Bình", "Chi" lần lượt vào bằng ba lần `Add` (ô mới màu xanh). Kết quả cuối: Count 3, Capacity 4. - Mở tab **Từ mảng có sẵn**. Hình chia hai bên: mảng `arr` và List `list`. Sau `new List<int>(arr)`, cả hai đều chứa 1, 2, 3. Khi `arr[0] = 99`, chỉ mảng đổi, còn `list[0]` vẫn in ra 1. ``` <iframe src="https://codegym-vn.github.io/programming-course-demos/c-sharp-ung-dung/cau-truc-du-lieu-nang-cao-collections/gioi-thieu-ve-collections-va-list-t-co-ban/khai-niem-va-khoi-tao-list-t/" title="Khởi tạo List<T>" style="border:0;" allowfullscreen></iframe> ``` Điều rút ra: `Count` là số phần tử thật, `Capacity` chỉ là chỗ đã chuẩn bị sẵn, và chỉ truy cập được chỉ số từ 0 đến `Count - 1`. Dù khởi tạo bằng cách nào, List cũng là một đối tượng riêng. List tạo từ mảng là bản chép, không liên kết với mảng. ## Lưu ý về List<object> Bạn có thể tạo `List<object>` để chứa nhiều kiểu khác nhau, nhưng nên tránh. Trình biên dịch không còn kiểm tra kiểu giúp bạn, ép kiểu sai sẽ gây `InvalidCastException`, và các kiểu giá trị như `int` bị đóng hộp (boxing) làm chậm chương trình. Hãy ưu tiên `List<T>` với một kiểu cụ thể. ## Tóm tắt - `List<T>` là danh sách có thứ tự, kích thước động, chứa các phần tử cùng kiểu `T`. - `Count` là số phần tử thật. `Capacity` là chỗ đã cấp sẵn, luôn lớn hơn hoặc bằng `Count`. - `new List<T>()` bắt đầu với Capacity 0. Lần `Add` đầu cấp sẵn 4 chỗ. - `new List<T>(n)` dành sẵn n chỗ nhưng List vẫn rỗng, chưa đọc được phần tử nào. - Collection initializer thực chất gọi `Add` cho từng giá trị. - `new List<T>(mảng)` chép dữ liệu sang List mới, đổi mảng sau đó không ảnh hưởng List.
A4: 3 | B4: 1. Cấu trúc dữ liệu nâng cao: Collections | C4: Giới thiệu về Collections và List<T> cơ bản | D4: Thêm, Truy cập và Xóa phần tử trong List<T> | E4: Bài đọc | F4: Nên làm | G4: Done | H4: Thấy các phần tử dịch chuyển thế nào khi Insert/Remove, và lỗi khi dùng chỉ số ngoài phạm vi. | I4: 1 cột, 4 tab | J4: Dãy ô có chỉ số. Ô mới trượt vào (vàng); khi chèn ở giữa, các ô phía sau trượt phải và chỉ số đổi (mũi tên 1→2, 2→3). Ô bị xóa mờ dần rồi các ô sau trượt trái. | K4: H01, H03 | L4: Add và Insert | Truy cập và sửa | Remove và RemoveAt | Lỗi chỉ số | M4: Add/Insert: fruits = {"Táo", "Cam"}. Add("Xoài") vào cuối (chỉ số 2). Insert(1, "Lê") → "Cam", "Xoài" dịch phải. Truy cập: fruits[0] đọc "Táo"; fruits[2] = "Nho" sửa tại chỗ, Count không đổi. Remove: Remove("Cam") xóa lần xuất hiện đầu tiên, các ô sau dịch trái, trả true. Remove("Dứa") không có → trả false, không lỗi. RemoveAt(0) xóa theo vị trí. Lỗi chỉ số: danh sách 3 phần tử, đọc fruits[3] → ArgumentOutOfRangeException; nhắc chỉ số hợp lệ 0..Count − 1. Bước cuối mỗi tab: tóm tắt trạng thái danh sách. | N4: Táo, Cam, Xoài, Lê, Nho, Dứa | O4: Thêm/xóa ở giữa làm dịch chỉ số các phần tử phía sau. Remove theo giá trị trả về bool, không ném lỗi khi không tìm thấy. | P4: RemoveAt/indexer với chỉ số sai ném ArgumentOutOfRangeException. Remove chỉ xóa lần xuất hiện đầu tiên. | Q4: c-sharp-ung-dung/cau-truc-du-lieu-nang-cao-collections/gioi-thieu-ve-collections-va-list-t-co-ban/them-truy-cap-va-xoa-phan-tu-trong-list-t/index.html | R4: https://codegym-vn.github.io/programming-course-demos/c-sharp-ung-dung/cau-truc-du-lieu-nang-cao-collections/gioi-thieu-ve-collections-va-list-t-co-ban/them-truy-cap-va-xoa-phan-tu-trong-list-t/ | V4: Sau khi đã nắm vững khái niệm về List<T> và cách khởi tạo một danh sách, bước tiếp theo là tìm hiểu cách tương tác với các phần tử bên trong nó. List<T> cung cấp các phương thức mạnh mẽ và trực quan để thêm, truy cập và xóa các phần tử, giúp bạn quản lý dữ liệu một cách linh hoạt. Thêm Phần tử vào List<T> Việc thêm phần tử là thao tác cơ bản đầu tiên khi làm việc với bất kỳ danh sách nào. List<T> hỗ trợ hai cách chính để thêm phần tử: vào cuối danh sách hoặc vào một vị trí cụ thể. Phương thức Add() Phương thức Add() được dùng để thêm một phần tử mới vào cuối danh sách. Đây là cách phổ biến nhất để bổ sung dữ liệu vào List<T>. List<string> danhSachMonHoc = new List<string>(); // Thêm các môn học vào cuối danh sách danhSachMonHoc.Add("Toán"); danhSachMonHoc.Add("Lý"); danhSachMonHoc.Add("Hóa"); Console.WriteLine("Danh sách môn học sau khi Add:"); foreach (string monHoc in danhSachMonHoc) { Console.WriteLine($"- {monHoc}"); } // Kết quả: // - Toán // - Lý // - Hóa Phương thức Insert() Khi bạn muốn thêm một phần tử vào một vị trí cụ thể trong danh sách, Insert() là phương thức phù hợp. Phương thức này nhận hai đối số: chỉ mục (index) nơi bạn muốn chèn và phần tử cần chèn. Các phần tử từ vị trí chèn trở đi sẽ được dịch chuyển sang phải. Lưu ý rằng chỉ mục phải nằm trong phạm vi từ 0 đến Count của danh sách. Nếu chỉ mục vượt quá phạm vi này, một ArgumentOutOfRangeException sẽ được ném ra. List<string> danhSachMonHoc = new List<string> { "Toán", "Lý", "Hóa" }; // Thêm "Văn" vào vị trí chỉ mục 1 (giữa Toán và Lý) danhSachMonHoc.Insert(1, "Văn"); Console.WriteLine("\nDanh sách môn học sau khi Insert:"); foreach (string monHoc in danhSachMonHoc) { Console.WriteLine($"- {monHoc}"); } // Kết quả: // - Toán // - Văn // - Lý // - Hóa Truy Cập Phần tử trong List<T> Để đọc hoặc thay đổi giá trị của một phần tử tại một vị trí cụ thể trong List<T>, bạn sử dụng indexer (chỉ mục) với cú pháp dấu ngoặc vuông []. Giống như mảng, List<T> sử dụng chỉ mục dựa trên 0, nghĩa là phần tử đầu tiên có chỉ mục 0, phần tử thứ hai có chỉ mục 1, v.v. List<int> danhSachSo = new List<int> { 10, 20, 30, 40, 50 }; // Truy cập phần tử tại chỉ mục 0 Console.WriteLine($"\nPhần tử đầu tiên: {danhSachSo[0]}"); // Kết quả: 10 // Truy cập phần tử tại chỉ mục 2 Console.WriteLine($"Phần tử thứ ba: {danhSachSo[2]}"); // Kết quả: 30 // Thay đổi giá trị của phần tử tại chỉ mục 1 danhSachSo[1] = 25; Console.WriteLine($"Phần tử thứ hai sau khi thay đổi: {danhSachSo[1]}"); // Kết quả: 25 // Lấy số lượng phần tử hiện có Console.WriteLine($"Số lượng phần tử trong danh sách: {danhSachSo.Count}"); // Kết quả: 5 // Thử truy cập một chỉ mục không hợp lệ sẽ gây ra lỗi // Console.WriteLine(danhSachSo[5]); // Sẽ ném ra System.ArgumentOutOfRangeException Việc truy cập phần tử bằng chỉ mục rất nhanh chóng và hiệu quả. Tuy nhiên, bạn cần đảm bảo chỉ mục nằm trong phạm vi từ 0 đến Count - 1. Nếu không, chương trình sẽ gặp lỗi ArgumentOutOfRangeException. Xóa Phần tử khỏi List<T> List<T> cung cấp nhiều phương thức để xóa phần tử, tùy thuộc vào việc bạn muốn xóa theo giá trị, theo vị trí hay xóa toàn bộ danh sách. Phương thức Remove() Phương thức Remove() được dùng để xóa lần xuất hiện đầu tiên của một phần tử có giá trị cụ thể trong danh sách. Nếu phần tử đó tồn tại và được xóa thành công, phương thức sẽ trả về true; ngược lại, nếu phần tử không tìm thấy, nó sẽ trả về false. List<string> danhSachTraiCay = new List<string> { "Táo", "Cam", "Chuối", "Táo", "Xoài" }; Console.WriteLine("\nDanh sách trái cây ban đầu:"); foreach (string traiCay in danhSachTraiCay) { Console.Write($"{traiCay} "); } Console.WriteLine(); // Xóa lần xuất hiện đầu tiên của "Táo" bool daXoaTao = danhSachTraiCay.Remove("Táo"); Console.WriteLine($"Đã xóa 'Táo'? {daXoaTao}"); // Kết quả: True Console.WriteLine("Danh sách trái cây sau khi xóa 'Táo':"); foreach (string traiCay in danhSachTraiCay) { Console.Write($"{traiCay} "); } Console.WriteLine(); // Kết quả: Cam Chuối Táo Xoài // Thử xóa một phần tử không tồn tại bool daXoaLe = danhSachTraiCay.Remove("Lê"); Console.WriteLine($"Đã xóa 'Lê'? {daXoaLe}"); // Kết quả: False Phương thức RemoveAt() Phương thức RemoveAt() xóa phần tử tại một chỉ mục cụ thể. Tương tự như Insert(), chỉ mục phải hợp lệ (từ 0 đến Count - 1). Các phần tử sau vị trí bị xóa sẽ tự động dịch chuyển sang trái. List<string> danhSachTraiCay = new List<string> { "Táo", "Cam", "Chuối", "Xoài" }; Console.WriteLine("\nDanh sách trái cây ban đầu:"); foreach (string traiCay in danhSachTraiCay) { Console.Write($"{traiCay} "); } Console.WriteLine(); // Xóa phần tử tại chỉ mục 1 (Cam) danhSachTraiCay.RemoveAt(1); Console.WriteLine("Danh sách trái cây sau khi xóa phần tử tại chỉ mục 1:"); foreach (string traiCay in danhSachTraiCay) { Console.Write($"{traiCay} "); } Console.WriteLine(); // Kết quả: Táo Chuối Xoài // Thử xóa tại một chỉ mục không hợp lệ sẽ gây ra lỗi // danhSachTraiCay.RemoveAt(10); // Sẽ ném ra System.ArgumentOutOfRangeException Phương thức Clear() Khi bạn muốn xóa tất cả các phần tử khỏi danh sách và làm cho nó trở thành một danh sách trống rỗng, phương thức Clear() là lựa chọn phù hợp nhất. List<string> danhSachTraiCay = new List<string> { "Táo", "Cam", "Chuối" }; Console.WriteLine($"\nSố lượng phần tử ban đầu: {danhSachTraiCay.Count}"); // Kết quả: 3 // Xóa tất cả các phần tử danhSachTraiCay.Clear(); Console.WriteLine($"Số lượng phần tử sau khi Clear: {danhSachTraiCay.Count}"); // Kết quả: 0 if (danhSachTraiCay.Count == 0) { Console.WriteLine("Danh sách trái cây hiện đang trống."); } Nắm vững các phương thức cơ bản này sẽ giúp bạn thao tác với dữ liệu trong List<T> một cách hiệu quả và linh hoạt, đặt nền tảng vững chắc cho việc sử dụng các cấu trúc dữ liệu phức tạp hơn trong C#. | W4: # Thêm, Truy cập và Xóa phần tử trong List<T> ## Mục tiêu học tập Sau bài học này, bạn có thể: - Phân biệt `Add` (thêm vào cuối) với `Insert` (chèn vào vị trí bất kỳ). - Đọc và sửa phần tử bằng chỉ số `list[i]`. - Phân biệt `Remove` (xóa theo giá trị) với `RemoveAt` (xóa theo vị trí), và dùng `Clear` để xóa hết. - Giải thích vì sao chỉ số ngoài khoảng 0 đến `Count - 1` gây `ArgumentOutOfRangeException`. - Quan sát các ô dịch chuyển và chỉ số thay đổi khi thêm, xóa bằng hoạt động mô phỏng. ## Thêm phần tử ### Add: thêm vào cuối `Add` đặt phần tử mới vào **cuối** danh sách. Các phần tử cũ giữ nguyên chỉ số. ### Insert: chèn vào vị trí bất kỳ `Insert(index, item)` chèn `item` tại chỉ số `index`. Các phần tử từ vị trí đó trở đi **dịch sang phải** một ô, nên chỉ số của chúng tăng thêm 1. Chỉ số hợp lệ cho `Insert` là từ 0 đến `Count` (chèn đúng bằng `Count` cũng được, tương đương `Add`). ```csharp using System; using System.Collections.Generic; public class Program { public static void Main() { var fruits = new List<string> { "Táo", "Cam" }; fruits.Add("Xoài"); // Táo, Cam, Xoài fruits.Insert(1, "Lê"); // Táo, Lê, Cam, Xoài Console.WriteLine(string.Join(", ", fruits)); // Táo, Lê, Cam, Xoài } } ``` ## Truy cập và sửa phần tử Dùng **indexer** `list[chỉ số]` để đọc hoặc ghi tại chỗ. Chỉ số bắt đầu từ 0. ```csharp var fruits = new List<string> { "Táo", "Cam", "Xoài" }; string s = fruits[0]; // "Táo", đọc không làm danh sách thay đổi fruits[2] = "Nho"; // thay "Xoài" bằng "Nho" ngay tại chỗ // Táo, Cam, Nho. Count vẫn là 3 ``` Sửa bằng chỉ số **không làm đổi `Count`**. ### Chỉ số hợp lệ Chỉ số hợp lệ là từ **0 đến `Count - 1`**. Ngoài khoảng đó, List ném `ArgumentOutOfRangeException`: ```csharp var fruits = new List<string> { "Táo", "Cam", "Xoài" }; string a = fruits[2]; // "Xoài", phần tử cuối string b = fruits[3]; // lỗi: ArgumentOutOfRangeException // Index was out of range. Must be non-negative and less than the size of the collection. (Parameter 'index') ``` ## Xóa phần tử | Phương thức | Xóa gì | Trả về | |---|---|---| | `Remove(item)` | Lần xuất hiện **đầu tiên** của giá trị | `bool`: `true` nếu xóa được, `false` nếu không thấy | | `RemoveAt(index)` | Phần tử tại chỉ số | Không trả về | | `Clear()` | Toàn bộ phần tử | Không trả về | Sau khi xóa, các phần tử phía sau **dịch sang trái** để lấp chỗ trống. ```csharp var fruits = new List<string> { "Táo", "Cam", "Xoài", "Lê" }; bool a = fruits.Remove("Cam"); // true, còn: Táo, Xoài, Lê bool b = fruits.Remove("Dứa"); // false, không có "Dứa", không ném lỗi fruits.RemoveAt(0); // xóa "Táo", còn: Xoài, Lê fruits.Clear(); // xóa hết, Count = 0 ``` `Remove` với giá trị không có chỉ trả về `false`. Còn `RemoveAt` với chỉ số ngoài khoảng 0 đến `Count - 1` thì ném `ArgumentOutOfRangeException`. ## Hoạt động: Các ô dịch chuyển Mô phỏng dưới đây có bốn tab, mỗi tab là một tình huống với danh sách `fruits`. Hãy thao tác theo thứ tự sau, bấm **Bước tiếp** để chạy từng dòng: - Mở tab **Add và Insert**. Danh sách ban đầu là "Táo" (chỉ số 0) và "Cam" (chỉ số 1). `Add("Xoài")` thêm ô mới màu xanh ở chỉ số 2. `Insert(1, "Lê")` chèn "Lê" vào chỉ số 1, còn "Cam" và "Xoài" dịch sang phải (nhãn nhỏ dưới ô ghi `1→2` và `2→3`). Danh sách cuối: Táo, Lê, Cam, Xoài. - Mở tab **Truy cập và sửa**. Danh sách có "Táo", "Cam", "Xoài". `fruits[0]` đọc ra "Táo" và danh sách không đổi. `fruits[2] = "Nho"` thay "Xoài" bằng "Nho" ngay tại chỗ, `Count` vẫn là 3. - Mở tab **Remove và RemoveAt**. Danh sách có Táo, Cam, Xoài, Lê. `Remove("Cam")` tìm thấy "Cam" ở chỉ số 1 và ô đó bị đánh dấu xóa. Sau đó "Xoài" và "Lê" dịch trái (nhãn `2→1` và `3→2`), `a` là `true`. `Remove("Dứa")` không thấy gì: các ô được tô mờ, `b` là `false`, danh sách giữ nguyên. `RemoveAt(0)` xóa "Táo", còn Xoài, Lê. - Mở tab **Lỗi chỉ số**. Danh sách có 3 phần tử nên chỉ số hợp lệ là 0 đến 2. `fruits[2]` đọc được "Xoài". `fruits[3]` làm hiện ô "?" đỏ và thẻ lỗi **ArgumentOutOfRangeException**, vì chỉ số 3 bằng `Count`. ``` <iframe src="https://codegym-vn.github.io/programming-course-demos/c-sharp-ung-dung/cau-truc-du-lieu-nang-cao-collections/gioi-thieu-ve-collections-va-list-t-co-ban/them-truy-cap-va-xoa-phan-tu-trong-list-t/" title="Thêm, truy cập và xóa phần tử trong List<T>" style="border:0;" allowfullscreen></iframe> ``` Điều rút ra: `Add` thêm vào cuối, còn `Insert` và các phép xóa làm các phần tử phía sau dịch chuyển, nên chỉ số của chúng thay đổi. Đọc hoặc ghi bằng chỉ số chỉ hợp lệ trong khoảng 0 đến `Count - 1`. ## Tóm tắt - `Add(x)` thêm vào cuối. `Insert(i, x)` chèn tại chỉ số `i` và đẩy các phần tử sau sang phải. - `list[i]` đọc hoặc sửa tại chỗ, không đổi `Count`. - Chỉ số hợp lệ là 0 đến `Count - 1`. Ngoài khoảng này ném `ArgumentOutOfRangeException`. - `Remove(x)` xóa lần xuất hiện đầu tiên và trả về `bool`. `RemoveAt(i)` xóa theo vị trí. `Clear()` xóa hết. - Sau mỗi lần xóa, các phần tử phía sau dịch sang trái.
